Workbook
Name Abteilung: Daten!$B$2:$B$30
Name Ansprechpartner: Daten!$C$2:$C$22
Name Auswahl_Bereich: Daten!$E$7:$E$8
Name Beschränkung: Daten!$R$15:$R$18
Name Brand_EX_Freisetzung1: Brand_EX!$B$31:$B$36
Name Brand_EX_Freisetzung2: Brand_EX!$B$37:$B$41
Name Brand_EX_GG: Brand_EX!$A$3:$A$7
Name Brand_EX_Mengengruppe: Brand_EX!$B$15:$B$17
Name Brand_EX_Mengengruppe2: Brand_EX!$B$18:$B$20
Name CMR: Daten!$O$2:$O$5
Name CMR_H: Daten!$M$2:$M$18
Name Einatmen_Freisetzung1: Einatmen!$B$38:$B$43
Name Einatmen_Freisetzung2: Einatmen!$B$44:$B$49
Name Einatmen_Mengengruppe: Einatmen!$B$21:$B$23
Name Einatmen_Mengengruppe2: Einatmen!$B$24:$B$26
Name Einheit_TRGS510: Daten!$H$12:$H$13
Name Einstufung_Weitere: Daten!$E$15:$E$16
Name Entsorgung: Entsorgung!$A$2:$B$975
Name Gebindeart: Daten!$K$2:$K$28
Name Gefahrgut: Gefahrgut!$A$2:$D$2328
Name Gefahrgut_UN: Gefahrgut!$A$2:$A$2328
Name Gefahrgut_VG: Daten!$U$2:$U$5
Name Gefahrstofflager: Daten!$D$2:$D$30
Name geringe_Gefährdung: Daten!$S$15:$S$27
Name GG_Einatmen: Einatmen!$A$12:$A$17
Name GG_Haut: Haut!$A$3:$A$8
Name Haut_Wirkdauer: Haut!$A$18:$A$19
Name Haut_Wirkfläche: Haut!$A$12:$A$13
Name Kennzeichnung: Daten!$F$2:$F$15
Name LGK: Daten!$J$2:$J$28
Name Mengeneinheit: Daten!$H$2:$H$5
Name PSA_Atemschutz: Daten!$X$2:$X$7
Name PSA_Augenschutz: Daten!$W$2:$W$4
Name PSA_Handschutz: Daten!$V$2:$V$4
Name PSA_Körperschutz: Daten!$Y$2:$Y$5
Name Schutzleitfaden_Auswahl: Schutzleitfäden!$A$2:$A$46
Name Standort: Daten!$A$2:$A$4
Name Status: Daten!$E$2:$E$4
Name Stoff_Gemisch: Daten!$E$11:$E$12
Name sub_Anforderungen: Daten!$P$2:$P$4
Name sub_auswahl: Daten!$S$2:$S$12
Name sub_Ergebnis: Daten!$S$2:$S$12
Name sub_Konsequenzen: Daten!$Q$2:$Q$6
Name sub_Preis: Daten!$R$2:$R$5
Name Verbrauch: Daten!$H$15:$H$21
Name Vorsorge: Daten!$Q$15:$Q$27
Name WGK: Daten!$I$2:$I$6
Name Zustand: Daten!$G$2:$G$3
Name Zustand_alle: Daten!$G$5:$G$13

Sheet Gefahrstoffverzeichnis
A1: Verzeichnis der Gefahr- und Gebrauchsstoffe | H1: Anzahl Gefahr- und Gebrauchsstoffe | U1: Betrieblicher Umgang | AO1: Lagermanagement | BZ1: Stoffeigenschaften | CT1: Inhalative Exposition | DE1: Dermale Exposition | DO1: Brand und Explosion | DZ1: Substitutionsprüfung | ED1: =HYPERLINK(CONCATENATE("Substitutionsprüfungen"),"1") -> 1 | EE1: Toxikologie | EZ1: Entsorgungshinweise | FG1: PSA | FV1: Gefahrgut / ADR | GB1: CAS-Nummer
D2: 45714 | L2: Summe Gefahrstoffe: | M2: =COUNTIF(Q8:Q20,"A")+COUNTIF(R8:R20,"G") -> 1 | X2: Büro | Y2: Lager | Z2: Produktion / Fertigung | AA2: Werkstatt | AB2: ... | AC2: … | AD2: ... | AE2: … | AF2: …
A3: KMG Arbeitssicherheit | L3: Summe Gebrauchsstoffe: | M3: =COUNTIF(CA8:CA20,"nicht als gefährlich eingestuft") -> 0
A4: Wolzenburg 2, 58566 Kierspe | L4: Anzahl gesamt: | M4: =M2+M3 -> 1
GC5: Format: XXXXXXX-XX-X
A6: Allgemeine Informationen zum Produkt | V6: [opt.] | AI6: [optional] | AJ6: [optional] | AM6: [optional] | AP6: Lagermanagement nach TRGS 510 | AW6: [optional] | AX6: Zusammenlagerungsverbote | CA6: Stoffeigenschaften | CP6: [optional] | CU6: Gefährdung durch inhalative Exposition (EMKG: Gefährlichkeitsgruppe "Einatmen" / TRGS 402) | DF6: Gefährdung durch Hautkontakt (EMKG: Gefährlichkeitsgruppe "Haut" / TRGS 401) | DP6: Gefährdung durch physikalische Reaktionen (EMKG: Gefährlichkeitsgruppe "Brand und Explosion") | EA6: Substitution nach TRGS 600 | EF6: Einstufung nach TRGS 410 / SVHC-Meldepflicht / Angaben zu den Bestandteilen (CMR) | FA6: Entsorgungshinweise | FE6: [optional] | FH6: Persönliche Schutzausrüstung | FJ6: [optional] | FK6: [optional] | FL6: [optional] | FM6: [optional] | FR6: [optional] | FU6: [optional] | FW6: Gefahrgut / ADR | GC6: CAS (engl.: Chemical Abstract Service Registry Number)
A7: Nr. | B7: Produktbezeichnung / Handelsname | C7: Hersteller / Lieferant | D7: Sicherheits- datenblatt (SDB) (Bearbeitungsdatum) | F7: Betriebs- anweisung (BAG) (Bearbeitungsdatum) | Q7: A | R7: G | S7: WGK | T7: Status | U7: + | V7: Bild | W7: Einsatzweck / interne Verwendung | AG7: Ansprechpartner | AH7: Tätigkeiten mit geringer Gefährdung (Gefährdungsbeurteilung nach TRGS 400) | AI7: interne Bestellnummer | AJ7: Sammelbetriebsanweisung | AK7: Revisionsstand zuletzt geprüft am | AL7: SDB freigegeben am | AM7: Technisches Datenblatt (TDB) (Ausgabedatum) | AO7: + | AP7: Lagerort | AQ7: Gebindeart | AR7: max. Gebindegröße | AS7: Mengeneinheit Gebinde | AT7: max. Lagermenge (Gebinde) | AU7: max. Lagermenge | AV7: Einheit | AW7: Verbrauch pro Jahr (Gebinde) | AX7: LGK | AY7: 1 | AZ7: 2A | BA7: 2B | BB7: 3 | BC7: 4.1A | BD7: 4.1B | BE7: 4.2 | BF7: 4.3 | BG7: 5.1A | BH7: 5.1B | BI7: 5.1C | BJ7: 5.2 | BK7: 6.1A | BL7: 6.1B | BM7: 6.1C | BN7: 6.1D | BO7: 6.2 | BP7: 7 | BQ7: 8A | BR7: 8B | BS7: 9 | BT7: 10 | BU7: 11 | BV7: 12 | BW7: 13 | BX7: 10-13 | BY7: Einheit (TRGS 510) | BZ7: + | CA7: Kennzeichnung gemäß CLP-VO (EG) 1272/2008 | CB7: H-Sätze 200-er | CC7: H-Sätze 300-er | CD7: H-Sätze 400-er | CE7: EUH-Sätze | CF7: P-Sätze 100-er | CG7: P-Sätze 200-er | CH7: P-Sätze 300-er | CI7: P-Sätze 400-er | CJ7: P-Sätze 500-er | CK7: Arbeitsplatzgrenzwerte (TRGS 900, DNEL) | CL7: Flamm- punkt [°C] | CM7: Siedepunkt [°C] | CN7: Dampfdruck bei 20°C [kPa] | CO7: Anwendungs- Temperatur [°C] | CP7: VOC [%] | CQ7: Stoff / Gemisch | CR7: Zustandsform | CS7: Farbe | CT7: + | CU7: GG Einatmen | CV7: Zustandsform | CW7: Mengen-gruppe | CX7: Einstufung | CY7: Verhalten | CZ7: Freisetzungs- gruppe | DA7: Maßnahmenreihe | DB7: Schutzleitfaden | DC7: öffnen | DD7: Beschreibung der Schutzmaßnahmen | DE7: + | DF7: GG Haut | DG7: Wirkfläche | DH7: Einstufung | DI7: Wirkdauer | DJ7: Einstufung | DK7: Maßnahmen-bedarf | DL7: Schutzleitfaden | DM7: öffnen | DN7: Beschreibung der Schutzmaßnahmen | DO7: + | DP7: GG Brand und EX | DQ7: Zustandsform | DR7: Mengen-gruppe | DS7: Einstufung | DT7: Verhalten | DU7: Freisetzungs- gruppe | DV7: Maßnahmenreihe | DW7: Schutzleitfaden | DX7: öffnen | DY7: Beschreibung der Schutzmaßnahmen | DZ7: + | EA7: Ergebnis der Substitutionsprüfung (Ersatzstoffsuche) | EB7: ersetzt durch SDB_XXX | EC7: Substitut / Ersatz für SDB_XXX | ED7: Bemerkung | EE7: + | EF7: Beschäftigungs-beschränkungen | EG7: Arbeitsmedizinische Vorsorge | EH7: PBT | EI7: vPvB | EJ7: Expositions-verzeichnis | EK7: Bezeichnung CMR-Inhaltsstoff (1) gemäß Abschnitt 3 SDB | EL7: Anteil [Gew.-%] | EM7: CMR Kategorie | EN7: H-Satz (CMR) | EO7: Wortlaut der Einstufung | EP7: Bezeichnung CMR-Inhaltsstoff (2) gemäß Abschnitt 3 SDB | EQ7: Anteil [Gew.-%] | ER7: CMR Kategorie | ES7: H-Satz (CMR) | ET7: Wortlaut der Einstufung | EU7: Bezeichnung CMR-Inhaltsstoff (3) gemäß Abschnitt 3 SDB | EV7: Anteil [Gew.-%] | EW7: CMR Kategorie | EX7: H-Satz (CMR) | EY7: Wortlaut der Einstufung | EZ7: + | FA7: Abfallschlüssel Produkt | FB7: Schlüsselbezeichnung Produkt | FC7: Abfallschlüssel Produkt / Verpackung | FD7: Schlüsselbezeichnung Produkt / Verpackung | FE7: Abfallschlüssel intern / tatsächlich | FF7: Schlüsselbezeichnung intern / tatsächlich | FG7: + | FH7: Handschutz | FI7: EN-Norm | FJ7: Material | FK7: Materialstärke [mm] | FL7: Durchdringzeit (max. Tragedauer) [min] | FM7: Zuordnung im PSA-Katalog | FN7: Augenschutz / Gesichtsschutz | FO7: EN-Norm | FP7: Körperschutz | FQ7: EN-Norm | FR7: Material | FS7: Atemschutz | FT7: EN-Norm | FU7: Filter | FV7: + | FW7: UN Nummer | FX7: Gefahrenzahl | FY7: Klasse | FZ7: Bezeichnung | GA7: Verpackungs-gruppe | GB7: + | GC7: CAS 1 | GD7: CAS 2 | GE7: CAS 3 | GF7: CAS 4 | GG7: CAS 5 | GH7: CAS 6 | GI7: CAS 7 | GJ7: CAS 8 | GK7: CAS 9 | GL7: CAS 10 | GM7: CAS 11 | GN7: CAS 12
A8: 001 | B8: OKS 250 Schmierstoff | C8: OKS Spezialschmierstoffe GmbH | D8: 44732 | E8: =HYPERLINK(CONCATENATE("SDB\SDB_",A8,".pdf"),"2") -> 2 | F8: 45714 | G8: =IF(AJ8<>"",HYPERLINK(CONCATENATE("BAG\",AJ8,".pdf"),"2"),HYPERLINK(CONCATENATE("BAG\BAG_",A8,".pdf"),"2")) -> 2 | H8: =IF(ISERROR(FIND("GHS 01",$CA8)),"","●") | I8: =IF(ISERROR(FIND("GHS 02",$CA8)),"","●") | J8: =IF(ISERROR(FIND("GHS 03",$CA8)),"","●") | K8: =IF(ISERROR(FIND("GHS 04",$CA8)),"","●") | L8: =IF(ISERROR(FIND("GHS 05",$CA8)),"","●") -> ● | M8: =IF(ISERROR(FIND("GHS 06",$CA8)),"","●") | N8: =IF(ISERROR(FIND("GHS 07",$CA8)),"","●") | O8: =IF(ISERROR(FIND("GHS 08",$CA8)),"","●") | P8: =IF(ISERROR(FIND("GHS 09",$CA8)),"","●") -> ● | Q8: =IF(ISERROR(FIND("Achtung",$CA8)),"","A") | R8: =IF(ISERROR(FIND("Gefahr",$CA8)),"","G") -> G | S8: 1 | T8: aktiv | V8: =HYPERLINK(CONCATENATE("Bilder\",A8,".jpg"),"y") -> y | W8: Schmierstoff von Werkzeugmaschinen | AG8: Abteilungsleiter | AN8: =HYPERLINK(CONCATENATE("TDB\TDB_",A8,".pdf"),"2") -> 2 | AQ8: Dose | AR8: 500 | AS8: ml | AU8: =IF(AS8="","",(IF(AS8="ml",(AR8/1000)*AT8,IF(AS8="Liter",AR8*AT8,IF(AS8="g",(AR8/1000)*AT8,IF(AS8="kg",AR8*AT8)))))) -> 0 | AV8: =IF(AS8="","",(IF(AS8="ml","Liter",IF(AS8="Liter","Liter",IF(AS8="g","kg",IF(AS8="kg","kg")))))) -> Liter | AY8: =IFERROR(VLOOKUP($AX8,Zusammenlagerung!$A$3:$AA$28,2,FALSE),"") | AZ8: =IFERROR(VLOOKUP($AX8,Zusammenlagerung!$A$3:$AA$28,3,FALSE),"") | BA8: =IFERROR(VLOOKUP($AX8,Zusammenlagerung!$A$3:$AA$28,4,FALSE),"") | BB8: =IFERROR(VLOOKUP($AX8,Zusammenlagerung!$A$3:$AA$28,5,FALSE),"") | BC8: =IFERROR(VLOOKUP($AX8,Zusammenlagerung!$A$3:$AA$28,6,FALSE),"") | BD8: =IFERROR(VLOOKUP($AX8,Zusammenlagerung!$A$3:$AA$28,7,FALSE),"") | BE8: =IFERROR(VLOOKUP($AX8,Zusammenlagerung!$A$3:$AA$28,8,FALSE),"") | BF8: =IFERROR(VLOOKUP($AX8,Zusammenlagerung!$A$3:$AA$28,9,FALSE),"") | BG8: =IFERROR(VLOOKUP($AX8,Zusammenlagerung!$A$3:$AA$28,10,FALSE),"") | BH8: =IFERROR(VLOOKUP($AX8,Zusammenlagerung!$A$3:$AA$28,11,FALSE),"") | BI8: =IFERROR(VLOOKUP($AX8,Zusammenlagerung!$A$3:$AA$28,12,FALSE),"") | BJ8: =IFERROR(VLOOKUP($AX8,Zusammenlagerung!$A$3:$AA$28,13,FALSE),"") | BK8: =IFERROR(VLOOKUP($AX8,Zusammenlagerung!$A$3:$AA$28,14,FALSE),"") | BL8: =IFERROR(VLOOKUP($AX8,Zusammenlagerung!$A$3:$AA$28,15,FALSE),"") | BM8: =IFERROR(VLOOKUP($AX8,Zusammenlagerung!$A$3:$AA$28,16,FALSE),"") | BN8: =IFERROR(VLOOKUP($AX8,Zusammenlagerung!$A$3:$AA$28,17,FALSE),"") | BO8: =IFERROR(VLOOKUP($AX8,Zusammenlagerung!$A$3:$AA$28,18,FALSE),"") | BP8: =IFERROR(VLOOKUP($AX8,Zusammenlagerung!$A$3:$AA$28,19,FALSE),"") | BQ8: =IFERROR(VLOOKUP($AX8,Zusammenlagerung!$A$3:$AA$28,20,FALSE),"") | BR8: =IFERROR(VLOOKUP($AX8,Zusammenlagerung!$A$3:$AA$28,21,FALSE),"") | BT8: =IFERROR(VLOOKUP($AX8,Zusammenlagerung!$A$3:$AA$28,23,FALSE),"") | BU8: =IFERROR(VLOOKUP($AX8,Zusammenlagerung!$A$3:$AA$28,24,FALSE),"") | BV8: =IFERROR(VLOOKUP($AX8,Zusammenlagerung!$A$3:$AA$28,25,FALSE),"") | BW8: =IFERROR(VLOOKUP($AX8,Zusammenlagerung!$A$3:$AA$28,26,FALSE),"") | BX8: =IFERROR(VLOOKUP($AX8,Zusammenlagerung!$A$3:$AA$28,27,FALSE),"") | BY8: =IF(CB8<>"",(IF(COUNTIFS(CB8,"*H220*")>0,"Liter",(IF(COUNTIFS(CB8,"*H221*")>0,"Liter",IF(COUNTIFS(CB8,"*H270*")>0,"Liter",IF(COUNTIFS(CB8,"*H280*")>0,"Liter",IF(COUNTIFS(CB8,"*H281*")>0,"Liter","kg"))))))),"") -> kg | CA8: GHS 05, GHS 09, Gefahr | CB8: - | CC8: H315, H318 | CD8: H410 | CE8: EUH208, EUH212 | CF8: - | CG8: P264, P273, P280 | CH8: P305 + P351 + P338, P310, P332 + P313, P391 | CI8: - | CJ8: - | CK8: Titandioxid; [in Pulverform mit <1 % Partikel mit aerodynamischem Durchmesser ≤ 10 μm], Calciumdihydroxid, Destillate (Erdöl), durch Lösungsmittel aufbereitete schwere paraffinhaltige; Basisöl — nicht spezifiziert, | CL8: - | CM8: - | CN8: 0 | CO8: 20 | CP8: 0 | CQ8: Gemisch | CR8: Paste | CS8: weiß | CX8: {=INDEX(Einatmen!$A$21:$A$26,MATCH(CV8&CW8,Einatmen!$C$21:$C$26&Einatmen!$B$21:$B$26,0))} -> #N/A | CZ8: {=INDEX(Einatmen!$A$38:$A$49,MATCH(CV8&CY8,Einatmen!$C$38:$C$49&Einatmen!$B$38:$B$49,0))} -> #N/A | DA8: {=INDEX(Einatmen!$D$52:$D$159,MATCH(CU8&CX8&CZ8&CV8,Einatmen!$A$52:$A$159&Einatmen!$B$52:$B$159&Einatmen!$C$52:$C$159&Einatmen!$E$52:$E$159,0))} -> #N/A | DC8: =IF(ISNA(DA8),"",(IF(DB8="","",(HYPERLINK(CONCATENATE("Schutzleitfäden\",DB8,".pdf"),"1"))))) | DD8: =IFERROR(VLOOKUP(DB8,Schutzleitfäden!$A$3:$C$46,3,FALSE),"") | DH8: =IF(DG8=Haut!$A$12,Haut!$B$12,(IF(DG8=Haut!$A$13,Haut!$B$13,""))) | DJ8: =IF(DI8=Haut!$A$18,Haut!$C$18,(IF(DI8=Haut!$A$19,Haut!$C$19,""))) | DK8: {=INDEX(Haut!$D$22:$D$45,MATCH(DF8&DH8&DJ8,Haut!$A$22:$A$45&Haut!$B$22:$B$45&Haut!$C$22:$C$45,0))} -> #N/A | DL8: =IF(ISNA(DK8),"",(IF(DK8=Haut!$D$49,Haut!$E$49,(IF(DK8=Haut!$D$50,Haut!$E$50,(IF(DK8=Haut!$D$51,Haut!$E$51,(IF(DK8=Haut!$D$52,Haut!$E$52,(IF(DK8=Haut!$D$53,Haut!$E$53,""))))))))))) | DM8: =IF(ISNA(DK8),"",(HYPERLINK(CONCATENATE("Schutzleitfäden\",DL8,".pdf"),"1"))) | DN8: =IFERROR(VLOOKUP(DL8,Schutzleitfäden!$A$3:$C$46,3,FALSE),"") | DQ8: =CV8 -> 0 | DR8: =CW8 -> 0 | DS8: {=INDEX(Brand_EX!$A$15:$A$20,MATCH(DQ8&DR8,Brand_EX!$C$15:$C$20&Brand_EX!$B$15:$B$20,0))} -> #N/A | DT8: =CY8 -> 0 | DU8: {=INDEX(Brand_EX!$A$31:$A$41,MATCH(DQ8&DT8,Brand_EX!$C$31:$C$41&Brand_EX!$B$31:$B$41,0))} -> #N/A | DV8: {=INDEX(Brand_EX!$D$44:$D$133,MATCH(DP8&DS8&DU8&DQ8,Brand_EX!$A$44:$A$133&Brand_EX!$B$44:$B$133&Brand_EX!$C$44:$C$133&Brand_EX!$E$44:$E$133,0))} -> #N/A | DX8: =IF(ISNA(DV8),"",(IF(DW8="","",(HYPERLINK(CONCATENATE("Schutzleitfäden\",DW8,".pdf"),"1"))))) | DY8: =IFERROR(VLOOKUP(DW8,Schutzleitfäden!$A$3:$C$46,3,FALSE),"") | EA8: Die Möglichkeit zur Substitution des Produktes ist zu prüfen. | EJ8: =IF(EM8="Kat. 1A","ja",IF(EM8="Kat. 1B","ja",IF(ER8="Kat. 1A","ja",IF(ER8="Kat. 1B","ja",IF(EW8="Kat. 1A","ja",IF(EW8="Kat. 1B","ja","nein")))))) -> nein | EO8: =VLOOKUP(EN8,Daten!$M$2:$N$18,2,FALSE) -> #N/A | EP8: - | EQ8: 0 | ER8: - | ES8: keine | ET8: =VLOOKUP(ES8,Daten!$M$2:$N$18,2,FALSE) -> entfällt | EU8: - | EV8: 0 | EW8: - | EX8: keine | EY8: =VLOOKUP(EX8,Daten!$M$2:$N$18,2,FALSE) -> entfällt | FB8: =IF(ISERROR(VLOOKUP(FA8,Entsorgung,2,FALSE)),"",VLOOKUP(FA8,Entsorgung,2,FALSE)) | FD8: =IF(ISERROR(VLOOKUP(FC8,Entsorgung,2,FALSE)),"",VLOOKUP(FC8,Entsorgung,2,FALSE)) | FF8: =IF(ISERROR(VLOOKUP(FE8,Entsorgung,2,FALSE)),"",VLOOKUP(FE8,Entsorgung,2,FALSE)) | FH8: Chemikalien-Schutzhandschuhe | FI8: EN 374 | FN8: Dichtschließende Schutzbrille mit Seitenschutz | FO8: EN 166 | FP8: (nicht definiert) | FS8: (nicht definiert) | FX8: =IF(ISERROR(VLOOKUP(FW8,Gefahrgut,2,FALSE)),"",VLOOKUP(FW8,Gefahrgut,2,FALSE)) | FY8: =IF(ISERROR(VLOOKUP(FW8,Gefahrgut,3,FALSE)),"",VLOOKUP(FW8,Gefahrgut,3,FALSE)) | FZ8: =IF(ISERROR(VLOOKUP(FW8,Gefahrgut,4,FALSE)),"",VLOOKUP(FW8,Gefahrgut,4,FALSE))
A9: 002 | B9: CARAMBA Super Das Original Multifunktions-Spray(Aerosol) | C9: CARAMBA CHEMIE GMBH & Co.KG | D9: … | E9: =HYPERLINK(CONCATENATE("SDB\SDB_",A9,".pdf"),"2") -> 2 | F9: … | G9: =IF(AJ9<>"",HYPERLINK(CONCATENATE("BAG\",AJ9,".pdf"),"2"),HYPERLINK(CONCATENATE("BAG\BAG_",A9,".pdf"),"2")) -> 2 | H9: =IF(ISERROR(FIND("GHS 01",$CA9)),"","●") | I9: =IF(ISERROR(FIND("GHS 02",$CA9)),"","●") | J9: =IF(ISERROR(FIND("GHS 03",$CA9)),"","●") | K9: =IF(ISERROR(FIND("GHS 04",$CA9)),"","●") | L9: =IF(ISERROR(FIND("GHS 05",$CA9)),"","●") | M9: =IF(ISERROR(FIND("GHS 06",$CA9)),"","●") | N9: =IF(ISERROR(FIND("GHS 07",$CA9)),"","●") | O9: =IF(ISERROR(FIND("GHS 08",$CA9)),"","●") | P9: =IF(ISERROR(FIND("GHS 09",$CA9)),"","●") | Q9: =IF(ISERROR(FIND("Achtung",$CA9)),"","A") | R9: =IF(ISERROR(FIND("Gefahr",$CA9)),"","G") | V9: =HYPERLINK(CONCATENATE("Bilder\",A9,".jpg"),"y") -> y | AG9: Abteilungsleiter | AN9: =HYPERLINK(CONCATENATE("TDB\TDB_",A9,".pdf"),"2") -> 2 | AQ9: Dose | AR9: 500 | AS9: ml | AU9: =IF(AS9="","",(IF(AS9="ml",(AR9/1000)*AT9,IF(AS9="Liter",AR9*AT9,IF(AS9="g",(AR9/1000)*AT9,IF(AS9="kg",AR9*AT9)))))) -> 0 | AV9: =IF(AS9="","",(IF(AS9="ml","Liter",IF(AS9="Liter","Liter",IF(AS9="g","kg",IF(AS9="kg","kg")))))) -> Liter | AY9: =IFERROR(VLOOKUP($AX9,Zusammenlagerung!$A$3:$AA$28,2,FALSE),"") | AZ9: =IFERROR(VLOOKUP($AX9,Zusammenlagerung!$A$3:$AA$28,3,FALSE),"") | BA9: =IFERROR(VLOOKUP($AX9,Zusammenlagerung!$A$3:$AA$28,4,FALSE),"") | BB9: =IFERROR(VLOOKUP($AX9,Zusammenlagerung!$A$3:$AA$28,5,FALSE),"") | BC9: =IFERROR(VLOOKUP($AX9,Zusammenlagerung!$A$3:$AA$28,6,FALSE),"") | BD9: =IFERROR(VLOOKUP($AX9,Zusammenlagerung!$A$3:$AA$28,7,FALSE),"") | BE9: =IFERROR(VLOOKUP($AX9,Zusammenlagerung!$A$3:$AA$28,8,FALSE),"") | BF9: =IFERROR(VLOOKUP($AX9,Zusammenlagerung!$A$3:$AA$28,9,FALSE),"") | BG9: =IFERROR(VLOOKUP($AX9,Zusammenlagerung!$A$3:$AA$28,10,FALSE),"") | BH9: =IFERROR(VLOOKUP($AX9,Zusammenlagerung!$A$3:$AA$28,11,FALSE),"") | BI9: =IFERROR(VLOOKUP($AX9,Zusammenlagerung!$A$3:$AA$28,12,FALSE),"") | BJ9: =IFERROR(VLOOKUP($AX9,Zusammenlagerung!$A$3:$AA$28,13,FALSE),"") | BK9: =IFERROR(VLOOKUP($AX9,Zusammenlagerung!$A$3:$AA$28,14,FALSE),"") | BL9: =IFERROR(VLOOKUP($AX9,Zusammenlagerung!$A$3:$AA$28,15,FALSE),"") | BM9: =IFERROR(VLOOKUP($AX9,Zusammenlagerung!$A$3:$AA$28,16,FALSE),"") | BN9: =IFERROR(VLOOKUP($AX9,Zusammenlagerung!$A$3:$AA$28,17,FALSE),"") | BO9: =IFERROR(VLOOKUP($AX9,Zusammenlagerung!$A$3:$AA$28,18,FALSE),"") | BP9: =IFERROR(VLOOKUP($AX9,Zusammenlagerung!$A$3:$AA$28,19,FALSE),"") | BQ9: =IFERROR(VLOOKUP($AX9,Zusammenlagerung!$A$3:$AA$28,20,FALSE),"") | BR9: =IFERROR(VLOOKUP($AX9,Zusammenlagerung!$A$3:$AA$28,21,FALSE),"") | BT9: =IFERROR(VLOOKUP($AX9,Zusammenlagerung!$A$3:$AA$28,23,FALSE),"") | BU9: =IFERROR(VLOOKUP($AX9,Zusammenlagerung!$A$3:$AA$28,24,FALSE),"") | BV9: =IFERROR(VLOOKUP($AX9,Zusammenlagerung!$A$3:$AA$28,25,FALSE),"") | BW9: =IFERROR(VLOOKUP($AX9,Zusammenlagerung!$A$3:$AA$28,26,FALSE),"") | BX9: =IFERROR(VLOOKUP($AX9,Zusammenlagerung!$A$3:$AA$28,27,FALSE),"") | BY9: =IF(CB9<>"",(IF(COUNTIFS(CB9,"*H220*")>0,"Liter",(IF(COUNTIFS(CB9,"*H221*")>0,"Liter",IF(COUNTIFS(CB9,"*H270*")>0,"Liter",IF(COUNTIFS(CB9,"*H280*")>0,"Liter",IF(COUNTIFS(CB9,"*H281*")>0,"Liter","kg"))))))),"") | CO9: 20 | CX9: {=INDEX(Einatmen!$A$21:$A$26,MATCH(CV9&CW9,Einatmen!$C$21:$C$26&Einatmen!$B$21:$B$26,0))} -> #N/A | CZ9: {=INDEX(Einatmen!$A$38:$A$49,MATCH(CV9&CY9,Einatmen!$C$38:$C$49&Einatmen!$B$38:$B$49,0))} -> #N/A | DA9: {=INDEX(Einatmen!$D$52:$D$159,MATCH(CU9&CX9&CZ9&CV9,Einatmen!$A$52:$A$159&Einatmen!$B$52:$B$159&Einatmen!$C$52:$C$159&Einatmen!$E$52:$E$159,0))} -> #N/A | DC9: =IF(ISNA(DA9),"",(IF(DB9="","",(HYPERLINK(CONCATENATE("Schutzleitfäden\",DB9,".pdf"),"1"))))) | DD9: =IFERROR(VLOOKUP(DB9,Schutzleitfäden!$A$3:$C$46,3,FALSE),"") | DH9: =IF(DG9=Haut!$A$12,Haut!$B$12,(IF(DG9=Haut!$A$13,Haut!$B$13,""))) | DJ9: =IF(DI9=Haut!$A$18,Haut!$C$18,(IF(DI9=Haut!$A$19,Haut!$C$19,""))) | DK9: {=INDEX(Haut!$D$22:$D$45,MATCH(DF9&DH9&DJ9,Haut!$A$22:$A$45&Haut!$B$22:$B$45&Haut!$C$22:$C$45,0))} -> #N/A | DL9: =IF(ISNA(DK9),"",(IF(DK9=Haut!$D$49,Haut!$E$49,(IF(DK9=Haut!$D$50,Haut!$E$50,(IF(DK9=Haut!$D$51,Haut!$E$51,(IF(DK9=Haut!$D$52,Haut!$E$52,(IF(DK9=Haut!$D$53,Haut!$E$53,""))))))))))) | DM9: =IF(ISNA(DK9),"",(HYPERLINK(CONCATENATE("Schutzleitfäden\",DL9,".pdf"),"1"))) | DN9: =IFERROR(VLOOKUP(DL9,Schutzleitfäden!$A$3:$C$46,3,FALSE),"") | DQ9: =CV9 -> 0 | DR9: =CW9 -> 0 | DS9: {=INDEX(Brand_EX!$A$15:$A$20,MATCH(DQ9&DR9,Brand_EX!$C$15:$C$20&Brand_EX!$B$15:$B$20,0))} -> #N/A | DT9: =CY9 -> 0 | DU9: {=INDEX(Brand_EX!$A$31:$A$41,MATCH(DQ9&DT9,Brand_EX!$C$31:$C$41&Brand_EX!$B$31:$B$41,0))} -> #N/A | DV9: {=INDEX(Brand_EX!$D$44:$D$133,MATCH(DP9&DS9&DU9&DQ9,Brand_EX!$A$44:$A$133&Brand_EX!$B$44:$B$133&Brand_EX!$C$44:$C$133&Brand_EX!$E$44:$E$133,0))} -> #N/A | DX9: =IF(ISNA(DV9),"",(IF(DW9="","",(HYPERLINK(CONCATENATE("Schutzleitfäden\",DW9,".pdf"),"1"))))) | DY9: =IFERROR(VLOOKUP(DW9,Schutzleitfäden!$A$3:$C$46,3,FALSE),"") | EA9: Die Möglichkeit zur Substitution des Produktes ist zu prüfen. | EJ9: =IF(EM9="Kat. 1A","ja",IF(EM9="Kat. 1B","ja",IF(ER9="Kat. 1A","ja",IF(ER9="Kat. 1B","ja",IF(EW9="Kat. 1A","ja",IF(EW9="Kat. 1B","ja","nein")))))) -> nein | EO9: =VLOOKUP(EN9,Daten!$M$2:$N$18,2,FALSE) -> #N/A | EP9: - | EQ9: 0 | ER9: - | ES9: keine | ET9: =VLOOKUP(ES9,Daten!$M$2:$N$18,2,FALSE) -> entfällt | EU9: - | EV9: 0 | EW9: - | EX9: keine | EY9: =VLOOKUP(EX9,Daten!$M$2:$N$18,2,FALSE) -> entfällt | FB9: =IF(ISERROR(VLOOKUP(FA9,Entsorgung,2,FALSE)),"",VLOOKUP(FA9,Entsorgung,2,FALSE)) | FD9: =IF(ISERROR(VLOOKUP(FC9,Entsorgung,2,FALSE)),"",VLOOKUP(FC9,Entsorgung,2,FALSE)) | FF9: =IF(ISERROR(VLOOKUP(FE9,Entsorgung,2,FALSE)),"",VLOOKUP(FE9,Entsorgung,2,FALSE)) | FH9: Chemikalien-Schutzhandschuhe | FI9: EN 374 | FN9: Dichtschließende Schutzbrille mit Seitenschutz | FO9: EN 166 | FP9: (nicht definiert) | FS9: (nicht definiert) | FX9: =IF(ISERROR(VLOOKUP(FW9,Gefahrgut,2,FALSE)),"",VLOOKUP(FW9,Gefahrgut,2,FALSE)) | FY9: =IF(ISERROR(VLOOKUP(FW9,Gefahrgut,3,FALSE)),"",VLOOKUP(FW9,Gefahrgut,3,FALSE)) | FZ9: =IF(ISERROR(VLOOKUP(FW9,Gefahrgut,4,FALSE)),"",VLOOKUP(FW9,Gefahrgut,4,FALSE))
A10: 003 | B10: DH556-AE2 A7201 Formreiniger | C10: hebrochemie GmbH | D10: … | E10: =HYPERLINK(CONCATENATE("SDB\SDB_",A10,".pdf"),"2") -> 2 | F10: … | G10: =IF(AJ10<>"",HYPERLINK(CONCATENATE("BAG\",AJ10,".pdf"),"2"),HYPERLINK(CONCATENATE("BAG\BAG_",A10,".pdf"),"2")) -> 2 | H10: =IF(ISERROR(FIND("GHS 01",$CA10)),"","●") | I10: =IF(ISERROR(FIND("GHS 02",$CA10)),"","●") | J10: =IF(ISERROR(FIND("GHS 03",$CA10)),"","●") | K10: =IF(ISERROR(FIND("GHS 04",$CA10)),"","●") | L10: =IF(ISERROR(FIND("GHS 05",$CA10)),"","●") | M10: =IF(ISERROR(FIND("GHS 06",$CA10)),"","●") | N10: =IF(ISERROR(FIND("GHS 07",$CA10)),"","●") | O10: =IF(ISERROR(FIND("GHS 08",$CA10)),"","●") | P10: =IF(ISERROR(FIND("GHS 09",$CA10)),"","●") | Q10: =IF(ISERROR(FIND("Achtung",$CA10)),"","A") | R10: =IF(ISERROR(FIND("Gefahr",$CA10)),"","G") | V10: =HYPERLINK(CONCATENATE("Bilder\",A10,".jpg"),"y") -> y | AG10: Abteilungsleiter | AN10: =HYPERLINK(CONCATENATE("TDB\TDB_",A10,".pdf"),"2") -> 2 | AQ10: Dose | AR10: 270 | AS10: ml | AU10: =IF(AS10="","",(IF(AS10="ml",(AR10/1000)*AT10,IF(AS10="Liter",AR10*AT10,IF(AS10="g",(AR10/1000)*AT10,IF(AS10="kg",AR10*AT10)))))) -> 0 | AV10: =IF(AS10="","",(IF(AS10="ml","Liter",IF(AS10="Liter","Liter",IF(AS10="g","kg",IF(AS10="kg","kg")))))) -> Liter | AY10: =IFERROR(VLOOKUP($AX10,Zusammenlagerung!$A$3:$AA$28,2,FALSE),"") | AZ10: =IFERROR(VLOOKUP($AX10,Zusammenlagerung!$A$3:$AA$28,3,FALSE),"") | BA10: =IFERROR(VLOOKUP($AX10,Zusammenlagerung!$A$3:$AA$28,4,FALSE),"") | BB10: =IFERROR(VLOOKUP($AX10,Zusammenlagerung!$A$3:$AA$28,5,FALSE),"") | BC10: =IFERROR(VLOOKUP($AX10,Zusammenlagerung!$A$3:$AA$28,6,FALSE),"") | BD10: =IFERROR(VLOOKUP($AX10,Zusammenlagerung!$A$3:$AA$28,7,FALSE),"") | BE10: =IFERROR(VLOOKUP($AX10,Zusammenlagerung!$A$3:$AA$28,8,FALSE),"") | BF10: =IFERROR(VLOOKUP($AX10,Zusammenlagerung!$A$3:$AA$28,9,FALSE),"") | BG10: =IFERROR(VLOOKUP($AX10,Zusammenlagerung!$A$3:$AA$28,10,FALSE),"") | BH10: =IFERROR(VLOOKUP($AX10,Zusammenlagerung!$A$3:$AA$28,11,FALSE),"") | BI10: =IFERROR(VLOOKUP($AX10,Zusammenlagerung!$A$3:$AA$28,12,FALSE),"") | BJ10: =IFERROR(VLOOKUP($AX10,Zusammenlagerung!$A$3:$AA$28,13,FALSE),"") | BK10: =IFERROR(VLOOKUP($AX10,Zusammenlagerung!$A$3:$AA$28,14,FALSE),"") | BL10: =IFERROR(VLOOKUP($AX10,Zusammenlagerung!$A$3:$AA$28,15,FALSE),"") | BM10: =IFERROR(VLOOKUP($AX10,Zusammenlagerung!$A$3:$AA$28,16,FALSE),"") | BN10: =IFERROR(VLOOKUP($AX10,Zusammenlagerung!$A$3:$AA$28,17,FALSE),"") | BO10: =IFERROR(VLOOKUP($AX10,Zusammenlagerung!$A$3:$AA$28,18,FALSE),"") | BP10: =IFERROR(VLOOKUP($AX10,Zusammenlagerung!$A$3:$AA$28,19,FALSE),"") | BQ10: =IFERROR(VLOOKUP($AX10,Zusammenlagerung!$A$3:$AA$28,20,FALSE),"") | BR10: =IFERROR(VLOOKUP($AX10,Zusammenlagerung!$A$3:$AA$28,21,FALSE),"") | BT10: =IFERROR(VLOOKUP($AX10,Zusammenlagerung!$A$3:$AA$28,23,FALSE),"") | BU10: =IFERROR(VLOOKUP($AX10,Zusammenlagerung!$A$3:$AA$28,24,FALSE),"") | BV10: =IFERROR(VLOOKUP($AX10,Zusammenlagerung!$A$3:$AA$28,25,FALSE),"") | BW10: =IFERROR(VLOOKUP($AX10,Zusammenlagerung!$A$3:$AA$28,26,FALSE),"") | BX10: =IFERROR(VLOOKUP($AX10,Zusammenlagerung!$A$3:$AA$28,27,FALSE),"") | BY10: =IF(CB10<>"",(IF(COUNTIFS(CB10,"*H220*")>0,"Liter",(IF(COUNTIFS(CB10,"*H221*")>0,"Liter",IF(COUNTIFS(CB10,"*H270*")>0,"Liter",IF(COUNTIFS(CB10,"*H280*")>0,"Liter",IF(COUNTIFS(CB10,"*H281*")>0,"Liter","kg"))))))),"") | CO10: 20 | CX10: {=INDEX(Einatmen!$A$21:$A$26,MATCH(CV10&CW10,Einatmen!$C$21:$C$26&Einatmen!$B$21:$B$26,0))} -> #N/A | CZ10: {=INDEX(Einatmen!$A$38:$A$49,MATCH(CV10&CY10,Einatmen!$C$38:$C$49&Einatmen!$B$38:$B$49,0))} -> #N/A | DA10: {=INDEX(Einatmen!$D$52:$D$159,MATCH(CU10&CX10&CZ10&CV10,Einatmen!$A$52:$A$159&Einatmen!$B$52:$B$159&Einatmen!$C$52:$C$159&Einatmen!$E$52:$E$159,0))} -> #N/A | DC10: =IF(ISNA(DA10),"",(IF(DB10="","",(HYPERLINK(CONCATENATE("Schutzleitfäden\",DB10,".pdf"),"1"))))) | DD10: =IFERROR(VLOOKUP(DB10,Schutzleitfäden!$A$3:$C$46,3,FALSE),"") | DH10: =IF(DG10=Haut!$A$12,Haut!$B$12,(IF(DG10=Haut!$A$13,Haut!$B$13,""))) | DJ10: =IF(DI10=Haut!$A$18,Haut!$C$18,(IF(DI10=Haut!$A$19,Haut!$C$19,""))) | DK10: {=INDEX(Haut!$D$22:$D$45,MATCH(DF10&DH10&DJ10,Haut!$A$22:$A$45&Haut!$B$22:$B$45&Haut!$C$22:$C$45,0))} -> #N/A | DL10: =IF(ISNA(DK10),"",(IF(DK10=Haut!$D$49,Haut!$E$49,(IF(DK10=Haut!$D$50,Haut!$E$50,(IF(DK10=Haut!$D$51,Haut!$E$51,(IF(DK10=Haut!$D$52,Haut!$E$52,(IF(DK10=Haut!$D$53,Haut!$E$53,""))))))))))) | DM10: =IF(ISNA(DK10),"",(HYPERLINK(CONCATENATE("Schutzleitfäden\",DL10,".pdf"),"1"))) | DN10: =IFERROR(VLOOKUP(DL10,Schutzleitfäden!$A$3:$C$46,3,FALSE),"") | DQ10: =CV10 -> 0 | DR10: =CW10 -> 0 | DS10: {=INDEX(Brand_EX!$A$15:$A$20,MATCH(DQ10&DR10,Brand_EX!$C$15:$C$20&Brand_EX!$B$15:$B$20,0))} -> #N/A | DT10: =CY10 -> 0 | DU10: {=INDEX(Brand_EX!$A$31:$A$41,MATCH(DQ10&DT10,Brand_EX!$C$31:$C$41&Brand_EX!$B$31:$B$41,0))} -> #N/A | DV10: {=INDEX(Brand_EX!$D$44:$D$133,MATCH(DP10&DS10&DU10&DQ10,Brand_EX!$A$44:$A$133&Brand_EX!$B$44:$B$133&Brand_EX!$C$44:$C$133&Brand_EX!$E$44:$E$133,0))} -> #N/A | DX10: =IF(ISNA(DV10),"",(IF(DW10="","",(HYPERLINK(CONCATENATE("Schutzleitfäden\",DW10,".pdf"),"1"))))) | DY10: =IFERROR(VLOOKUP(DW10,Schutzleitfäden!$A$3:$C$46,3,FALSE),"") | EA10: Die Möglichkeit zur Substitution des Produktes ist zu prüfen. | EJ10: =IF(EM10="Kat. 1A","ja",IF(EM10="Kat. 1B","ja",IF(ER10="Kat. 1A","ja",IF(ER10="Kat. 1B","ja",IF(EW10="Kat. 1A","ja",IF(EW10="Kat. 1B","ja","nein")))))) -> nein | EO10: =VLOOKUP(EN10,Daten!$M$2:$N$18,2,FALSE) -> #N/A | EP10: - | EQ10: 0 | ER10: - | ES10: keine | ET10: =VLOOKUP(ES10,Daten!$M$2:$N$18,2,FALSE) -> entfällt | EU10: - | EV10: 0 | EW10: - | EX10: keine | EY10: =VLOOKUP(EX10,Daten!$M$2:$N$18,2,FALSE) -> entfällt | FB10: =IF(ISERROR(VLOOKUP(FA10,Entsorgung,2,FALSE)),"",VLOOKUP(FA10,Entsorgung,2,FALSE)) | FD10: =IF(ISERROR(VLOOKUP(FC10,Entsorgung,2,FALSE)),"",VLOOKUP(FC10,Entsorgung,2,FALSE)) | FF10: =IF(ISERROR(VLOOKUP(FE10,Entsorgung,2,FALSE)),"",VLOOKUP(FE10,Entsorgung,2,FALSE)) | FH10: Chemikalien-Schutzhandschuhe | FI10: EN 374 | FN10: Dichtschließende Schutzbrille mit Seitenschutz | FO10: EN 166 | FP10: (nicht definiert) | FS10: (nicht definiert) | FX10: =IF(ISERROR(VLOOKUP(FW10,Gefahrgut,2,FALSE)),"",VLOOKUP(FW10,Gefahrgut,2,FALSE)) | FY10: =IF(ISERROR(VLOOKUP(FW10,Gefahrgut,3,FALSE)),"",VLOOKUP(FW10,Gefahrgut,3,FALSE)) | FZ10: =IF(ISERROR(VLOOKUP(FW10,Gefahrgut,4,FALSE)),"",VLOOKUP(FW10,Gefahrgut,4,FALSE))
A11: 004 | B11: ALGOREX Spiritus | C11: MEYER-CHEMIE GmbH & Co KG | E11: =HYPERLINK(CONCATENATE("SDB\SDB_",A11,".pdf"),"2") -> 2 | G11: =IF(AJ11<>"",HYPERLINK(CONCATENATE("BAG\",AJ11,".pdf"),"2"),HYPERLINK(CONCATENATE("BAG\BAG_",A11,".pdf"),"2")) -> 2 | H11: =IF(ISERROR(FIND("GHS 01",$CA11)),"","●") | I11: =IF(ISERROR(FIND("GHS 02",$CA11)),"","●") | J11: =IF(ISERROR(FIND("GHS 03",$CA11)),"","●") | K11: =IF(ISERROR(FIND("GHS 04",$CA11)),"","●") | L11: =IF(ISERROR(FIND("GHS 05",$CA11)),"","●") | M11: =IF(ISERROR(FIND("GHS 06",$CA11)),"","●") | N11: =IF(ISERROR(FIND("GHS 07",$CA11)),"","●") | O11: =IF(ISERROR(FIND("GHS 08",$CA11)),"","●") | P11: =IF(ISERROR(FIND("GHS 09",$CA11)),"","●") | Q11: =IF(ISERROR(FIND("Achtung",$CA11)),"","A") | R11: =IF(ISERROR(FIND("Gefahr",$CA11)),"","G") | V11: =HYPERLINK(CONCATENATE("Bilder\",A11,".jpg"),"y") -> y | AG11: Abteilungsleiter | AN11: =HYPERLINK(CONCATENATE("TDB\TDB_",A11,".pdf"),"2") -> 2 | AQ11: Kunststoff-Flasche | AR11: 1 | AS11: Liter | AU11: =IF(AS11="","",(IF(AS11="ml",(AR11/1000)*AT11,IF(AS11="Liter",AR11*AT11,IF(AS11="g",(AR11/1000)*AT11,IF(AS11="kg",AR11*AT11)))))) -> 0 | AV11: =IF(AS11="","",(IF(AS11="ml","Liter",IF(AS11="Liter","Liter",IF(AS11="g","kg",IF(AS11="kg","kg")))))) -> Liter | AY11: =IFERROR(VLOOKUP($AX11,Zusammenlagerung!$A$3:$AA$28,2,FALSE),"") | AZ11: =IFERROR(VLOOKUP($AX11,Zusammenlagerung!$A$3:$AA$28,3,FALSE),"") | BA11: =IFERROR(VLOOKUP($AX11,Zusammenlagerung!$A$3:$AA$28,4,FALSE),"") | BB11: =IFERROR(VLOOKUP($AX11,Zusammenlagerung!$A$3:$AA$28,5,FALSE),"") | BC11: =IFERROR(VLOOKUP($AX11,Zusammenlagerung!$A$3:$AA$28,6,FALSE),"") | BD11: =IFERROR(VLOOKUP($AX11,Zusammenlagerung!$A$3:$AA$28,7,FALSE),"") | BE11: =IFERROR(VLOOKUP($AX11,Zusammenlagerung!$A$3:$AA$28,8,FALSE),"") | BF11: =IFERROR(VLOOKUP($AX11,Zusammenlagerung!$A$3:$AA$28,9,FALSE),"") | BG11: =IFERROR(VLOOKUP($AX11,Zusammenlagerung!$A$3:$AA$28,10,FALSE),"") | BH11: =IFERROR(VLOOKUP($AX11,Zusammenlagerung!$A$3:$AA$28,11,FALSE),"") | BI11: =IFERROR(VLOOKUP($AX11,Zusammenlagerung!$A$3:$AA$28,12,FALSE),"") | BJ11: =IFERROR(VLOOKUP($AX11,Zusammenlagerung!$A$3:$AA$28,13,FALSE),"") | BK11: =IFERROR(VLOOKUP($AX11,Zusammenlagerung!$A$3:$AA$28,14,FALSE),"") | BL11: =IFERROR(VLOOKUP($AX11,Zusammenlagerung!$A$3:$AA$28,15,FALSE),"") | BM11: =IFERROR(VLOOKUP($AX11,Zusammenlagerung!$A$3:$AA$28,16,FALSE),"") | BN11: =IFERROR(VLOOKUP($AX11,Zusammenlagerung!$A$3:$AA$28,17,FALSE),"") | BO11: =IFERROR(VLOOKUP($AX11,Zusammenlagerung!$A$3:$AA$28,18,FALSE),"") | BP11: =IFERROR(VLOOKUP($AX11,Zusammenlagerung!$A$3:$AA$28,19,FALSE),"") | BQ11: =IFERROR(VLOOKUP($AX11,Zusammenlagerung!$A$3:$AA$28,20,FALSE),"") | BR11: =IFERROR(VLOOKUP($AX11,Zusammenlagerung!$A$3:$AA$28,21,FALSE),"") | BT11: =IFERROR(VLOOKUP($AX11,Zusammenlagerung!$A$3:$AA$28,23,FALSE),"") | BU11: =IFERROR(VLOOKUP($AX11,Zusammenlagerung!$A$3:$AA$28,24,FALSE),"") | BV11: =IFERROR(VLOOKUP($AX11,Zusammenlagerung!$A$3:$AA$28,25,FALSE),"") | BW11: =IFERROR(VLOOKUP($AX11,Zusammenlagerung!$A$3:$AA$28,26,FALSE),"") | BX11: =IFERROR(VLOOKUP($AX11,Zusammenlagerung!$A$3:$AA$28,27,FALSE),"") | BY11: =IF(CB11<>"",(IF(COUNTIFS(CB11,"*H220*")>0,"Liter",(IF(COUNTIFS(CB11,"*H221*")>0,"Liter",IF(COUNTIFS(CB11,"*H270*")>0,"Liter",IF(COUNTIFS(CB11,"*H280*")>0,"Liter",IF(COUNTIFS(CB11,"*H281*")>0,"Liter","kg"))))))),"") | CO11: 20 | CX11: {=INDEX(Einatmen!$A$21:$A$26,MATCH(CV11&CW11,Einatmen!$C$21:$C$26&Einatmen!$B$21:$B$26,0))} -> #N/A | CZ11: {=INDEX(Einatmen!$A$38:$A$49,MATCH(CV11&CY11,Einatmen!$C$38:$C$49&Einatmen!$B$38:$B$49,0))} -> #N/A | DA11: {=INDEX(Einatmen!$D$52:$D$159,MATCH(CU11&CX11&CZ11&CV11,Einatmen!$A$52:$A$159&Einatmen!$B$52:$B$159&Einatmen!$C$52:$C$159&Einatmen!$E$52:$E$159,0))} -> #N/A | DC11: =IF(ISNA(DA11),"",(IF(DB11="","",(HYPERLINK(CONCATENATE("Schutzleitfäden\",DB11,".pdf"),"1"))))) | DD11: =IFERROR(VLOOKUP(DB11,Schutzleitfäden!$A$3:$C$46,3,FALSE),"") | DH11: =IF(DG11=Haut!$A$12,Haut!$B$12,(IF(DG11=Haut!$A$13,Haut!$B$13,""))) | DJ11: =IF(DI11=Haut!$A$18,Haut!$C$18,(IF(DI11=Haut!$A$19,Haut!$C$19,""))) | DK11: {=INDEX(Haut!$D$22:$D$45,MATCH(DF11&DH11&DJ11,Haut!$A$22:$A$45&Haut!$B$22:$B$45&Haut!$C$22:$C$45,0))} -> #N/A | DL11: =IF(ISNA(DK11),"",(IF(DK11=Haut!$D$49,Haut!$E$49,(IF(DK11=Haut!$D$50,Haut!$E$50,(IF(DK11=Haut!$D$51,Haut!$E$51,(IF(DK11=Haut!$D$52,Haut!$E$52,(IF(DK11=Haut!$D$53,Haut!$E$53,""))))))))))) | DM11: =IF(ISNA(DK11),"",(HYPERLINK(CONCATENATE("Schutzleitfäden\",DL11,".pdf"),"1"))) | DN11: =IFERROR(VLOOKUP(DL11,Schutzleitfäden!$A$3:$C$46,3,FALSE),"") | DQ11: =CV11 -> 0 | DR11: =CW11 -> 0 | DS11: {=INDEX(Brand_EX!$A$15:$A$20,MATCH(DQ11&DR11,Brand_EX!$C$15:$C$20&Brand_EX!$B$15:$B$20,0))} -> #N/A | DT11: =CY11 -> 0 | DU11: {=INDEX(Brand_EX!$A$31:$A$41,MATCH(DQ11&DT11,Brand_EX!$C$31:$C$41&Brand_EX!$B$31:$B$41,0))} -> #N/A | DV11: {=INDEX(Brand_EX!$D$44:$D$133,MATCH(DP11&DS11&DU11&DQ11,Brand_EX!$A$44:$A$133&Brand_EX!$B$44:$B$133&Brand_EX!$C$44:$C$133&Brand_EX!$E$44:$E$133,0))} -> #N/A | DX11: =IF(ISNA(DV11),"",(IF(DW11="","",(HYPERLINK(CONCATENATE("Schutzleitfäden\",DW11,".pdf"),"1"))))) | DY11: =IFERROR(VLOOKUP(DW11,Schutzleitfäden!$A$3:$C$46,3,FALSE),"") | EA11: Die Möglichkeit zur Substitution des Produktes ist zu prüfen. | EJ11: =IF(EM11="Kat. 1A","ja",IF(EM11="Kat. 1B","ja",IF(ER11="Kat. 1A","ja",IF(ER11="Kat. 1B","ja",IF(EW11="Kat. 1A","ja",IF(EW11="Kat. 1B","ja","nein")))))) -> nein | EO11: =VLOOKUP(EN11,Daten!$M$2:$N$18,2,FALSE) -> #N/A | EP11: - | EQ11: 0 | ER11: - | ES11: keine | ET11: =VLOOKUP(ES11,Daten!$M$2:$N$18,2,FALSE) -> entfällt | EU11: - | EV11: 0 | EW11: - | EX11: keine | EY11: =VLOOKUP(EX11,Daten!$M$2:$N$18,2,FALSE) -> entfällt | FB11: =IF(ISERROR(VLOOKUP(FA11,Entsorgung,2,FALSE)),"",VLOOKUP(FA11,Entsorgung,2,FALSE)) | FD11: =IF(ISERROR(VLOOKUP(FC11,Entsorgung,2,FALSE)),"",VLOOKUP(FC11,Entsorgung,2,FALSE)) | FF11: =IF(ISERROR(VLOOKUP(FE11,Entsorgung,2,FALSE)),"",VLOOKUP(FE11,Entsorgung,2,FALSE)) | FH11: Chemikalien-Schutzhandschuhe | FI11: EN 374 | FN11: Dichtschließende Schutzbrille mit Seitenschutz | FO11: EN 166 | FP11: (nicht definiert) | FS11: (nicht definiert) | FX11: =IF(ISERROR(VLOOKUP(FW11,Gefahrgut,2,FALSE)),"",VLOOKUP(FW11,Gefahrgut,2,FALSE)) | FY11: =IF(ISERROR(VLOOKUP(FW11,Gefahrgut,3,FALSE)),"",VLOOKUP(FW11,Gefahrgut,3,FALSE)) | FZ11: =IF(ISERROR(VLOOKUP(FW11,Gefahrgut,4,FALSE)),"",VLOOKUP(FW11,Gefahrgut,4,FALSE))
A12: 005 | B12: A.C.S. 3 | C12: Bremer & Leguil GmbH | E12: =HYPERLINK(CONCATENATE("SDB\SDB_",A12,".pdf"),"2") -> 2 | G12: =IF(AJ12<>"",HYPERLINK(CONCATENATE("BAG\",AJ12,".pdf"),"2"),HYPERLINK(CONCATENATE("BAG\BAG_",A12,".pdf"),"2")) -> 2 | H12: =IF(ISERROR(FIND("GHS 01",$CA12)),"","●") | I12: =IF(ISERROR(FIND("GHS 02",$CA12)),"","●") | J12: =IF(ISERROR(FIND("GHS 03",$CA12)),"","●") | K12: =IF(ISERROR(FIND("GHS 04",$CA12)),"","●") | L12: =IF(ISERROR(FIND("GHS 05",$CA12)),"","●") | M12: =IF(ISERROR(FIND("GHS 06",$CA12)),"","●") | N12: =IF(ISERROR(FIND("GHS 07",$CA12)),"","●") | O12: =IF(ISERROR(FIND("GHS 08",$CA12)),"","●") | P12: =IF(ISERROR(FIND("GHS 09",$CA12)),"","●") | Q12: =IF(ISERROR(FIND("Achtung",$CA12)),"","A") | R12: =IF(ISERROR(FIND("Gefahr",$CA12)),"","G") | V12: =HYPERLINK(CONCATENATE("Bilder\",A12,".jpg"),"y") -> y | AG12: Abteilungsleiter | AN12: =HYPERLINK(CONCATENATE("TDB\TDB_",A12,".pdf"),"2") -> 2 | AQ12: Dose | AR12: 750 | AS12: ml | AU12: =IF(AS12="","",(IF(AS12="ml",(AR12/1000)*AT12,IF(AS12="Liter",AR12*AT12,IF(AS12="g",(AR12/1000)*AT12,IF(AS12="kg",AR12*AT12)))))) -> 0 | AV12: =IF(AS12="","",(IF(AS12="ml","Liter",IF(AS12="Liter","Liter",IF(AS12="g","kg",IF(AS12="kg","kg")))))) -> Liter | AY12: =IFERROR(VLOOKUP($AX12,Zusammenlagerung!$A$3:$AA$28,2,FALSE),"") | AZ12: =IFERROR(VLOOKUP($AX12,Zusammenlagerung!$A$3:$AA$28,3,FALSE),"") | BA12: =IFERROR(VLOOKUP($AX12,Zusammenlagerung!$A$3:$AA$28,4,FALSE),"") | BB12: =IFERROR(VLOOKUP($AX12,Zusammenlagerung!$A$3:$AA$28,5,FALSE),"") | BC12: =IFERROR(VLOOKUP($AX12,Zusammenlagerung!$A$3:$AA$28,6,FALSE),"") | BD12: =IFERROR(VLOOKUP($AX12,Zusammenlagerung!$A$3:$AA$28,7,FALSE),"") | BE12: =IFERROR(VLOOKUP($AX12,Zusammenlagerung!$A$3:$AA$28,8,FALSE),"") | BF12: =IFERROR(VLOOKUP($AX12,Zusammenlagerung!$A$3:$AA$28,9,FALSE),"") | BG12: =IFERROR(VLOOKUP($AX12,Zusammenlagerung!$A$3:$AA$28,10,FALSE),"") | BH12: =IFERROR(VLOOKUP($AX12,Zusammenlagerung!$A$3:$AA$28,11,FALSE),"") | BI12: =IFERROR(VLOOKUP($AX12,Zusammenlagerung!$A$3:$AA$28,12,FALSE),"") | BJ12: =IFERROR(VLOOKUP($AX12,Zusammenlagerung!$A$3:$AA$28,13,FALSE),"") | BK12: =IFERROR(VLOOKUP($AX12,Zusammenlagerung!$A$3:$AA$28,14,FALSE),"") | BL12: =IFERROR(VLOOKUP($AX12,Zusammenlagerung!$A$3:$AA$28,15,FALSE),"") | BM12: =IFERROR(VLOOKUP($AX12,Zusammenlagerung!$A$3:$AA$28,16,FALSE),"") | BN12: =IFERROR(VLOOKUP($AX12,Zusammenlagerung!$A$3:$AA$28,17,FALSE),"") | BO12: =IFERROR(VLOOKUP($AX12,Zusammenlagerung!$A$3:$AA$28,18,FALSE),"") | BP12: =IFERROR(VLOOKUP($AX12,Zusammenlagerung!$A$3:$AA$28,19,FALSE),"") | BQ12: =IFERROR(VLOOKUP($AX12,Zusammenlagerung!$A$3:$AA$28,20,FALSE),"") | BR12: =IFERROR(VLOOKUP($AX12,Zusammenlagerung!$A$3:$AA$28,21,FALSE),"") | BT12: =IFERROR(VLOOKUP($AX12,Zusammenlagerung!$A$3:$AA$28,23,FALSE),"") | BU12: =IFERROR(VLOOKUP($AX12,Zusammenlagerung!$A$3:$AA$28,24,FALSE),"") | BV12: =IFERROR(VLOOKUP($AX12,Zusammenlagerung!$A$3:$AA$28,25,FALSE),"") | BW12: =IFERROR(VLOOKUP($AX12,Zusammenlagerung!$A$3:$AA$28,26,FALSE),"") | BX12: =IFERROR(VLOOKUP($AX12,Zusammenlagerung!$A$3:$AA$28,27,FALSE),"") | BY12: =IF(CB12<>"",(IF(COUNTIFS(CB12,"*H220*")>0,"Liter",(IF(COUNTIFS(CB12,"*H221*")>0,"Liter",IF(COUNTIFS(CB12,"*H270*")>0,"Liter",IF(COUNTIFS(CB12,"*H280*")>0,"Liter",IF(COUNTIFS(CB12,"*H281*")>0,"Liter","kg"))))))),"") | CO12: 20 | CX12: {=INDEX(Einatmen!$A$21:$A$26,MATCH(CV12&CW12,Einatmen!$C$21:$C$26&Einatmen!$B$21:$B$26,0))} -> #N/A | CZ12: {=INDEX(Einatmen!$A$38:$A$49,MATCH(CV12&CY12,Einatmen!$C$38:$C$49&Einatmen!$B$38:$B$49,0))} -> #N/A | DA12: {=INDEX(Einatmen!$D$52:$D$159,MATCH(CU12&CX12&CZ12&CV12,Einatmen!$A$52:$A$159&Einatmen!$B$52:$B$159&Einatmen!$C$52:$C$159&Einatmen!$E$52:$E$159,0))} -> #N/A | DC12: =IF(ISNA(DA12),"",(IF(DB12="","",(HYPERLINK(CONCATENATE("Schutzleitfäden\",DB12,".pdf"),"1"))))) | DD12: =IFERROR(VLOOKUP(DB12,Schutzleitfäden!$A$3:$C$46,3,FALSE),"") | DH12: =IF(DG12=Haut!$A$12,Haut!$B$12,(IF(DG12=Haut!$A$13,Haut!$B$13,""))) | DJ12: =IF(DI12=Haut!$A$18,Haut!$C$18,(IF(DI12=Haut!$A$19,Haut!$C$19,""))) | DK12: {=INDEX(Haut!$D$22:$D$45,MATCH(DF12&DH12&DJ12,Haut!$A$22:$A$45&Haut!$B$22:$B$45&Haut!$C$22:$C$45,0))} -> #N/A | DL12: =IF(ISNA(DK12),"",(IF(DK12=Haut!$D$49,Haut!$E$49,(IF(DK12=Haut!$D$50,Haut!$E$50,(IF(DK12=Haut!$D$51,Haut!$E$51,(IF(DK12=Haut!$D$52,Haut!$E$52,(IF(DK12=Haut!$D$53,Haut!$E$53,""))))))))))) | DM12: =IF(ISNA(DK12),"",(HYPERLINK(CONCATENATE("Schutzleitfäden\",DL12,".pdf"),"1"))) | DN12: =IFERROR(VLOOKUP(DL12,Schutzleitfäden!$A$3:$C$46,3,FALSE),"") | DQ12: =CV12 -> 0 | DR12: =CW12 -> 0 | DS12: {=INDEX(Brand_EX!$A$15:$A$20,MATCH(DQ12&DR12,Brand_EX!$C$15:$C$20&Brand_EX!$B$15:$B$20,0))} -> #N/A | DT12: =CY12 -> 0 | DU12: {=INDEX(Brand_EX!$A$31:$A$41,MATCH(DQ12&DT12,Brand_EX!$C$31:$C$41&Brand_EX!$B$31:$B$41,0))} -> #N/A | DV12: {=INDEX(Brand_EX!$D$44:$D$133,MATCH(DP12&DS12&DU12&DQ12,Brand_EX!$A$44:$A$133&Brand_EX!$B$44:$B$133&Brand_EX!$C$44:$C$133&Brand_EX!$E$44:$E$133,0))} -> #N/A | DX12: =IF(ISNA(DV12),"",(IF(DW12="","",(HYPERLINK(CONCATENATE("Schutzleitfäden\",DW12,".pdf"),"1"))))) | DY12: =IFERROR(VLOOKUP(DW12,Schutzleitfäden!$A$3:$C$46,3,FALSE),"") | EA12: Die Möglichkeit zur Substitution des Produktes ist zu prüfen. | EJ12: =IF(EM12="Kat. 1A","ja",IF(EM12="Kat. 1B","ja",IF(ER12="Kat. 1A","ja",IF(ER12="Kat. 1B","ja",IF(EW12="Kat. 1A","ja",IF(EW12="Kat. 1B","ja","nein")))))) -> nein | EO12: =VLOOKUP(EN12,Daten!$M$2:$N$18,2,FALSE) -> #N/A | EP12: - | EQ12: 0 | ER12: - | ES12: keine | ET12: =VLOOKUP(ES12,Daten!$M$2:$N$18,2,FALSE) -> entfällt | EU12: - | EV12: 0 | EW12: - | EX12: keine | EY12: =VLOOKUP(EX12,Daten!$M$2:$N$18,2,FALSE) -> entfällt | FB12: =IF(ISERROR(VLOOKUP(FA12,Entsorgung,2,FALSE)),"",VLOOKUP(FA12,Entsorgung,2,FALSE)) | FD12: =IF(ISERROR(VLOOKUP(FC12,Entsorgung,2,FALSE)),"",VLOOKUP(FC12,Entsorgung,2,FALSE)) | FF12: =IF(ISERROR(VLOOKUP(FE12,Entsorgung,2,FALSE)),"",VLOOKUP(FE12,Entsorgung,2,FALSE)) | FH12: Chemikalien-Schutzhandschuhe | FI12: EN 374 | FN12: Dichtschließende Schutzbrille mit Seitenschutz | FO12: EN 166 | FP12: (nicht definiert) | FS12: (nicht definiert) | FX12: =IF(ISERROR(VLOOKUP(FW12,Gefahrgut,2,FALSE)),"",VLOOKUP(FW12,Gefahrgut,2,FALSE)) | FY12: =IF(ISERROR(VLOOKUP(FW12,Gefahrgut,3,FALSE)),"",VLOOKUP(FW12,Gefahrgut,3,FALSE)) | FZ12: =IF(ISERROR(VLOOKUP(FW12,Gefahrgut,4,FALSE)),"",VLOOKUP(FW12,Gefahrgut,4,FALSE))
A13: 006 | B13: Metaflux 75-17 Citrus-Reiniger (Spray) | C13: TECHNO-SERVICE GmbH | E13: =HYPERLINK(CONCATENATE("SDB\SDB_",A13,".pdf"),"2") -> 2 | G13: =IF(AJ13<>"",HYPERLINK(CONCATENATE("BAG\",AJ13,".pdf"),"2"),HYPERLINK(CONCATENATE("BAG\BAG_",A13,".pdf"),"2")) -> 2 | H13: =IF(ISERROR(FIND("GHS 01",$CA13)),"","●") | I13: =IF(ISERROR(FIND("GHS 02",$CA13)),"","●") | J13: =IF(ISERROR(FIND("GHS 03",$CA13)),"","●") | K13: =IF(ISERROR(FIND("GHS 04",$CA13)),"","●") | L13: =IF(ISERROR(FIND("GHS 05",$CA13)),"","●") | M13: =IF(ISERROR(FIND("GHS 06",$CA13)),"","●") | N13: =IF(ISERROR(FIND("GHS 07",$CA13)),"","●") | O13: =IF(ISERROR(FIND("GHS 08",$CA13)),"","●") | P13: =IF(ISERROR(FIND("GHS 09",$CA13)),"","●") | Q13: =IF(ISERROR(FIND("Achtung",$CA13)),"","A") | R13: =IF(ISERROR(FIND("Gefahr",$CA13)),"","G") | V13: =HYPERLINK(CONCATENATE("Bilder\",A13,".jpg"),"y") -> y | AG13: Abteilungsleiter | AN13: =HYPERLINK(CONCATENATE("TDB\TDB_",A13,".pdf"),"2") -> 2 | AQ13: Dose | AR13: 400 | AS13: ml | AU13: =IF(AS13="","",(IF(AS13="ml",(AR13/1000)*AT13,IF(AS13="Liter",AR13*AT13,IF(AS13="g",(AR13/1000)*AT13,IF(AS13="kg",AR13*AT13)))))) -> 0 | AV13: =IF(AS13="","",(IF(AS13="ml","Liter",IF(AS13="Liter","Liter",IF(AS13="g","kg",IF(AS13="kg","kg")))))) -> Liter | AY13: =IFERROR(VLOOKUP($AX13,Zusammenlagerung!$A$3:$AA$28,2,FALSE),"") | AZ13: =IFERROR(VLOOKUP($AX13,Zusammenlagerung!$A$3:$AA$28,3,FALSE),"") | BA13: =IFERROR(VLOOKUP($AX13,Zusammenlagerung!$A$3:$AA$28,4,FALSE),"") | BB13: =IFERROR(VLOOKUP($AX13,Zusammenlagerung!$A$3:$AA$28,5,FALSE),"") | BC13: =IFERROR(VLOOKUP($AX13,Zusammenlagerung!$A$3:$AA$28,6,FALSE),"") | BD13: =IFERROR(VLOOKUP($AX13,Zusammenlagerung!$A$3:$AA$28,7,FALSE),"") | BE13: =IFERROR(VLOOKUP($AX13,Zusammenlagerung!$A$3:$AA$28,8,FALSE),"") | BF13: =IFERROR(VLOOKUP($AX13,Zusammenlagerung!$A$3:$AA$28,9,FALSE),"") | BG13: =IFERROR(VLOOKUP($AX13,Zusammenlagerung!$A$3:$AA$28,10,FALSE),"") | BH13: =IFERROR(VLOOKUP($AX13,Zusammenlagerung!$A$3:$AA$28,11,FALSE),"") | BI13: =IFERROR(VLOOKUP($AX13,Zusammenlagerung!$A$3:$AA$28,12,FALSE),"") | BJ13: =IFERROR(VLOOKUP($AX13,Zusammenlagerung!$A$3:$AA$28,13,FALSE),"") | BK13: =IFERROR(VLOOKUP($AX13,Zusammenlagerung!$A$3:$AA$28,14,FALSE),"") | BL13: =IFERROR(VLOOKUP($AX13,Zusammenlagerung!$A$3:$AA$28,15,FALSE),"") | BM13: =IFERROR(VLOOKUP($AX13,Zusammenlagerung!$A$3:$AA$28,16,FALSE),"") | BN13: =IFERROR(VLOOKUP($AX13,Zusammenlagerung!$A$3:$AA$28,17,FALSE),"") | BO13: =IFERROR(VLOOKUP($AX13,Zusammenlagerung!$A$3:$AA$28,18,FALSE),"") | BP13: =IFERROR(VLOOKUP($AX13,Zusammenlagerung!$A$3:$AA$28,19,FALSE),"") | BQ13: =IFERROR(VLOOKUP($AX13,Zusammenlagerung!$A$3:$AA$28,20,FALSE),"") | BR13: =IFERROR(VLOOKUP($AX13,Zusammenlagerung!$A$3:$AA$28,21,FALSE),"") | BT13: =IFERROR(VLOOKUP($AX13,Zusammenlagerung!$A$3:$AA$28,23,FALSE),"") | BU13: =IFERROR(VLOOKUP($AX13,Zusammenlagerung!$A$3:$AA$28,24,FALSE),"") | BV13: =IFERROR(VLOOKUP($AX13,Zusammenlagerung!$A$3:$AA$28,25,FALSE),"") | BW13: =IFERROR(VLOOKUP($AX13,Zusammenlagerung!$A$3:$AA$28,26,FALSE),"") | BX13: =IFERROR(VLOOKUP($AX13,Zusammenlagerung!$A$3:$AA$28,27,FALSE),"") | BY13: =IF(CB13<>"",(IF(COUNTIFS(CB13,"*H220*")>0,"Liter",(IF(COUNTIFS(CB13,"*H221*")>0,"Liter",IF(COUNTIFS(CB13,"*H270*")>0,"Liter",IF(COUNTIFS(CB13,"*H280*")>0,"Liter",IF(COUNTIFS(CB13,"*H281*")>0,"Liter","kg"))))))),"") | CO13: 20 | CX13: {=INDEX(Einatmen!$A$21:$A$26,MATCH(CV13&CW13,Einatmen!$C$21:$C$26&Einatmen!$B$21:$B$26,0))} -> #N/A | CZ13: {=INDEX(Einatmen!$A$38:$A$49,MATCH(CV13&CY13,Einatmen!$C$38:$C$49&Einatmen!$B$38:$B$49,0))} -> #N/A | DA13: {=INDEX(Einatmen!$D$52:$D$159,MATCH(CU13&CX13&CZ13&CV13,Einatmen!$A$52:$A$159&Einatmen!$B$52:$B$159&Einatmen!$C$52:$C$159&Einatmen!$E$52:$E$159,0))} -> #N/A | DC13: =IF(ISNA(DA13),"",(IF(DB13="","",(HYPERLINK(CONCATENATE("Schutzleitfäden\",DB13,".pdf"),"1"))))) | DD13: =IFERROR(VLOOKUP(DB13,Schutzleitfäden!$A$3:$C$46,3,FALSE),"") | DH13: =IF(DG13=Haut!$A$12,Haut!$B$12,(IF(DG13=Haut!$A$13,Haut!$B$13,""))) | DJ13: =IF(DI13=Haut!$A$18,Haut!$C$18,(IF(DI13=Haut!$A$19,Haut!$C$19,""))) | DK13: {=INDEX(Haut!$D$22:$D$45,MATCH(DF13&DH13&DJ13,Haut!$A$22:$A$45&Haut!$B$22:$B$45&Haut!$C$22:$C$45,0))} -> #N/A | DL13: =IF(ISNA(DK13),"",(IF(DK13=Haut!$D$49,Haut!$E$49,(IF(DK13=Haut!$D$50,Haut!$E$50,(IF(DK13=Haut!$D$51,Haut!$E$51,(IF(DK13=Haut!$D$52,Haut!$E$52,(IF(DK13=Haut!$D$53,Haut!$E$53,""))))))))))) | DM13: =IF(ISNA(DK13),"",(HYPERLINK(CONCATENATE("Schutzleitfäden\",DL13,".pdf"),"1"))) | DN13: =IFERROR(VLOOKUP(DL13,Schutzleitfäden!$A$3:$C$46,3,FALSE),"") | DQ13: =CV13 -> 0 | DR13: =CW13 -> 0 | DS13: {=INDEX(Brand_EX!$A$15:$A$20,MATCH(DQ13&DR13,Brand_EX!$C$15:$C$20&Brand_EX!$B$15:$B$20,0))} -> #N/A | DT13: =CY13 -> 0 | DU13: {=INDEX(Brand_EX!$A$31:$A$41,MATCH(DQ13&DT13,Brand_EX!$C$31:$C$41&Brand_EX!$B$31:$B$41,0))} -> #N/A | DV13: {=INDEX(Brand_EX!$D$44:$D$133,MATCH(DP13&DS13&DU13&DQ13,Brand_EX!$A$44:$A$133&Brand_EX!$B$44:$B$133&Brand_EX!$C$44:$C$133&Brand_EX!$E$44:$E$133,0))} -> #N/A | DX13: =IF(ISNA(DV13),"",(IF(DW13="","",(HYPERLINK(CONCATENATE("Schutzleitfäden\",DW13,".pdf"),"1"))))) | DY13: =IFERROR(VLOOKUP(DW13,Schutzleitfäden!$A$3:$C$46,3,FALSE),"") | EA13: Die Möglichkeit zur Substitution des Produktes ist zu prüfen. | EJ13: =IF(EM13="Kat. 1A","ja",IF(EM13="Kat. 1B","ja",IF(ER13="Kat. 1A","ja",IF(ER13="Kat. 1B","ja",IF(EW13="Kat. 1A","ja",IF(EW13="Kat. 1B","ja","nein")))))) -> nein | EO13: =VLOOKUP(EN13,Daten!$M$2:$N$18,2,FALSE) -> #N/A | EP13: - | EQ13: 0 | ER13: - | ES13: keine | ET13: =VLOOKUP(ES13,Daten!$M$2:$N$18,2,FALSE) -> entfällt | EU13: - | EV13: 0 | EW13: - | EX13: keine | EY13: =VLOOKUP(EX13,Daten!$M$2:$N$18,2,FALSE) -> entfällt | FB13: =IF(ISERROR(VLOOKUP(FA13,Entsorgung,2,FALSE)),"",VLOOKUP(FA13,Entsorgung,2,FALSE)) | FD13: =IF(ISERROR(VLOOKUP(FC13,Entsorgung,2,FALSE)),"",VLOOKUP(FC13,Entsorgung,2,FALSE)) | FF13: =IF(ISERROR(VLOOKUP(FE13,Entsorgung,2,FALSE)),"",VLOOKUP(FE13,Entsorgung,2,FALSE)) | FH13: Chemikalien-Schutzhandschuhe | FI13: EN 374 | FN13: Dichtschließende Schutzbrille mit Seitenschutz | FO13: EN 166 | FP13: (nicht definiert) | FS13: (nicht definiert) | FX13: =IF(ISERROR(VLOOKUP(FW13,Gefahrgut,2,FALSE)),"",VLOOKUP(FW13,Gefahrgut,2,FALSE)) | FY13: =IF(ISERROR(VLOOKUP(FW13,Gefahrgut,3,FALSE)),"",VLOOKUP(FW13,Gefahrgut,3,FALSE)) | FZ13: =IF(ISERROR(VLOOKUP(FW13,Gefahrgut,4,FALSE)),"",VLOOKUP(FW13,Gefahrgut,4,FALSE))
A14: 007 | B14: Cramolin Plastik | C14: ITW Chemische Produkte GmbH & Co. KG | E14: =HYPERLINK(CONCATENATE("SDB\SDB_",A14,".pdf"),"2") -> 2 | G14: =IF(AJ14<>"",HYPERLINK(CONCATENATE("BAG\",AJ14,".pdf"),"2"),HYPERLINK(CONCATENATE("BAG\BAG_",A14,".pdf"),"2")) -> 2 | H14: =IF(ISERROR(FIND("GHS 01",$CA14)),"","●") | I14: =IF(ISERROR(FIND("GHS 02",$CA14)),"","●") | J14: =IF(ISERROR(FIND("GHS 03",$CA14)),"","●") | K14: =IF(ISERROR(FIND("GHS 04",$CA14)),"","●") | L14: =IF(ISERROR(FIND("GHS 05",$CA14)),"","●") | M14: =IF(ISERROR(FIND("GHS 06",$CA14)),"","●") | N14: =IF(ISERROR(FIND("GHS 07",$CA14)),"","●") | O14: =IF(ISERROR(FIND("GHS 08",$CA14)),"","●") | P14: =IF(ISERROR(FIND("GHS 09",$CA14)),"","●") | Q14: =IF(ISERROR(FIND("Achtung",$CA14)),"","A") | R14: =IF(ISERROR(FIND("Gefahr",$CA14)),"","G") | V14: =HYPERLINK(CONCATENATE("Bilder\",A14,".jpg"),"y") -> y | AG14: Abteilungsleiter | AN14: =HYPERLINK(CONCATENATE("TDB\TDB_",A14,".pdf"),"2") -> 2 | AQ14: Dose | AR14: 200 | AS14: ml | AU14: =IF(AS14="","",(IF(AS14="ml",(AR14/1000)*AT14,IF(AS14="Liter",AR14*AT14,IF(AS14="g",(AR14/1000)*AT14,IF(AS14="kg",AR14*AT14)))))) -> 0 | AV14: =IF(AS14="","",(IF(AS14="ml","Liter",IF(AS14="Liter","Liter",IF(AS14="g","kg",IF(AS14="kg","kg")))))) -> Liter | AY14: =IFERROR(VLOOKUP($AX14,Zusammenlagerung!$A$3:$AA$28,2,FALSE),"") | AZ14: =IFERROR(VLOOKUP($AX14,Zusammenlagerung!$A$3:$AA$28,3,FALSE),"") | BA14: =IFERROR(VLOOKUP($AX14,Zusammenlagerung!$A$3:$AA$28,4,FALSE),"") | BB14: =IFERROR(VLOOKUP($AX14,Zusammenlagerung!$A$3:$AA$28,5,FALSE),"") | BC14: =IFERROR(VLOOKUP($AX14,Zusammenlagerung!$A$3:$AA$28,6,FALSE),"") | BD14: =IFERROR(VLOOKUP($AX14,Zusammenlagerung!$A$3:$AA$28,7,FALSE),"") | BE14: =IFERROR(VLOOKUP($AX14,Zusammenlagerung!$A$3:$AA$28,8,FALSE),"") | BF14: =IFERROR(VLOOKUP($AX14,Zusammenlagerung!$A$3:$AA$28,9,FALSE),"") | BG14: =IFERROR(VLOOKUP($AX14,Zusammenlagerung!$A$3:$AA$28,10,FALSE),"") | BH14: =IFERROR(VLOOKUP($AX14,Zusammenlagerung!$A$3:$AA$28,11,FALSE),"") | BI14: =IFERROR(VLOOKUP($AX14,Zusammenlagerung!$A$3:$AA$28,12,FALSE),"") | BJ14: =IFERROR(VLOOKUP($AX14,Zusammenlagerung!$A$3:$AA$28,13,FALSE),"") | BK14: =IFERROR(VLOOKUP($AX14,Zusammenlagerung!$A$3:$AA$28,14,FALSE),"") | BL14: =IFERROR(VLOOKUP($AX14,Zusammenlagerung!$A$3:$AA$28,15,FALSE),"") | BM14: =IFERROR(VLOOKUP($AX14,Zusammenlagerung!$A$3:$AA$28,16,FALSE),"") | BN14: =IFERROR(VLOOKUP($AX14,Zusammenlagerung!$A$3:$AA$28,17,FALSE),"") | BO14: =IFERROR(VLOOKUP($AX14,Zusammenlagerung!$A$3:$AA$28,18,FALSE),"") | BP14: =IFERROR(VLOOKUP($AX14,Zusammenlagerung!$A$3:$AA$28,19,FALSE),"") | BQ14: =IFERROR(VLOOKUP($AX14,Zusammenlagerung!$A$3:$AA$28,20,FALSE),"") | BR14: =IFERROR(VLOOKUP($AX14,Zusammenlagerung!$A$3:$AA$28,21,FALSE),"") | BT14: =IFERROR(VLOOKUP($AX14,Zusammenlagerung!$A$3:$AA$28,23,FALSE),"") | BU14: =IFERROR(VLOOKUP($AX14,Zusammenlagerung!$A$3:$AA$28,24,FALSE),"") | BV14: =IFERROR(VLOOKUP($AX14,Zusammenlagerung!$A$3:$AA$28,25,FALSE),"") | BW14: =IFERROR(VLOOKUP($AX14,Zusammenlagerung!$A$3:$AA$28,26,FALSE),"") | BX14: =IFERROR(VLOOKUP($AX14,Zusammenlagerung!$A$3:$AA$28,27,FALSE),"") | BY14: =IF(CB14<>"",(IF(COUNTIFS(CB14,"*H220*")>0,"Liter",(IF(COUNTIFS(CB14,"*H221*")>0,"Liter",IF(COUNTIFS(CB14,"*H270*")>0,"Liter",IF(COUNTIFS(CB14,"*H280*")>0,"Liter",IF(COUNTIFS(CB14,"*H281*")>0,"Liter","kg"))))))),"") | CO14: 20 | CX14: {=INDEX(Einatmen!$A$21:$A$26,MATCH(CV14&CW14,Einatmen!$C$21:$C$26&Einatmen!$B$21:$B$26,0))} -> #N/A | CZ14: {=INDEX(Einatmen!$A$38:$A$49,MATCH(CV14&CY14,Einatmen!$C$38:$C$49&Einatmen!$B$38:$B$49,0))} -> #N/A | DA14: {=INDEX(Einatmen!$D$52:$D$159,MATCH(CU14&CX14&CZ14&CV14,Einatmen!$A$52:$A$159&Einatmen!$B$52:$B$159&Einatmen!$C$52:$C$159&Einatmen!$E$52:$E$159,0))} -> #N/A | DC14: =IF(ISNA(DA14),"",(IF(DB14="","",(HYPERLINK(CONCATENATE("Schutzleitfäden\",DB14,".pdf"),"1"))))) | DD14: =IFERROR(VLOOKUP(DB14,Schutzleitfäden!$A$3:$C$46,3,FALSE),"") | DH14: =IF(DG14=Haut!$A$12,Haut!$B$12,(IF(DG14=Haut!$A$13,Haut!$B$13,""))) | DJ14: =IF(DI14=Haut!$A$18,Haut!$C$18,(IF(DI14=Haut!$A$19,Haut!$C$19,""))) | DK14: {=INDEX(Haut!$D$22:$D$45,MATCH(DF14&DH14&DJ14,Haut!$A$22:$A$45&Haut!$B$22:$B$45&Haut!$C$22:$C$45,0))} -> #N/A | DL14: =IF(ISNA(DK14),"",(IF(DK14=Haut!$D$49,Haut!$E$49,(IF(DK14=Haut!$D$50,Haut!$E$50,(IF(DK14=Haut!$D$51,Haut!$E$51,(IF(DK14=Haut!$D$52,Haut!$E$52,(IF(DK14=Haut!$D$53,Haut!$E$53,""))))))))))) | DM14: =IF(ISNA(DK14),"",(HYPERLINK(CONCATENATE("Schutzleitfäden\",DL14,".pdf"),"1"))) | DN14: =IFERROR(VLOOKUP(DL14,Schutzleitfäden!$A$3:$C$46,3,FALSE),"") | DQ14: =CV14 -> 0 | DR14: =CW14 -> 0 | DS14: {=INDEX(Brand_EX!$A$15:$A$20,MATCH(DQ14&DR14,Brand_EX!$C$15:$C$20&Brand_EX!$B$15:$B$20,0))} -> #N/A | DT14: =CY14 -> 0 | DU14: {=INDEX(Brand_EX!$A$31:$A$41,MATCH(DQ14&DT14,Brand_EX!$C$31:$C$41&Brand_EX!$B$31:$B$41,0))} -> #N/A | DV14: {=INDEX(Brand_EX!$D$44:$D$133,MATCH(DP14&DS14&DU14&DQ14,Brand_EX!$A$44:$A$133&Brand_EX!$B$44:$B$133&Brand_EX!$C$44:$C$133&Brand_EX!$E$44:$E$133,0))} -> #N/A | DX14: =IF(ISNA(DV14),"",(IF(DW14="","",(HYPERLINK(CONCATENATE("Schutzleitfäden\",DW14,".pdf"),"1"))))) | DY14: =IFERROR(VLOOKUP(DW14,Schutzleitfäden!$A$3:$C$46,3,FALSE),"") | EA14: Die Möglichkeit zur Substitution des Produktes ist zu prüfen. | EJ14: =IF(EM14="Kat. 1A","ja",IF(EM14="Kat. 1B","ja",IF(ER14="Kat. 1A","ja",IF(ER14="Kat. 1B","ja",IF(EW14="Kat. 1A","ja",IF(EW14="Kat. 1B","ja","nein")))))) -> nein | EO14: =VLOOKUP(EN14,Daten!$M$2:$N$18,2,FALSE) -> #N/A | EP14: - | EQ14: 0 | ER14: - | ES14: keine | ET14: =VLOOKUP(ES14,Daten!$M$2:$N$18,2,FALSE) -> entfällt | EU14: - | EV14: 0 | EW14: - | EX14: keine | EY14: =VLOOKUP(EX14,Daten!$M$2:$N$18,2,FALSE) -> entfällt | FB14: =IF(ISERROR(VLOOKUP(FA14,Entsorgung,2,FALSE)),"",VLOOKUP(FA14,Entsorgung,2,FALSE)) | FD14: =IF(ISERROR(VLOOKUP(FC14,Entsorgung,2,FALSE)),"",VLOOKUP(FC14,Entsorgung,2,FALSE)) | FF14: =IF(ISERROR(VLOOKUP(FE14,Entsorgung,2,FALSE)),"",VLOOKUP(FE14,Entsorgung,2,FALSE)) | FH14: Chemikalien-Schutzhandschuhe | FI14: EN 374 | FN14: Dichtschließende Schutzbrille mit Seitenschutz | FO14: EN 166 | FP14: (nicht definiert) | FS14: (nicht definiert) | FX14: =IF(ISERROR(VLOOKUP(FW14,Gefahrgut,2,FALSE)),"",VLOOKUP(FW14,Gefahrgut,2,FALSE)) | FY14: =IF(ISERROR(VLOOKUP(FW14,Gefahrgut,3,FALSE)),"",VLOOKUP(FW14,Gefahrgut,3,FALSE)) | FZ14: =IF(ISERROR(VLOOKUP(FW14,Gefahrgut,4,FALSE)),"",VLOOKUP(FW14,Gefahrgut,4,FALSE))
A15: 008 | B15: D555-AE2 Z 263 | C15: hebrochemie GmbH | E15: =HYPERLINK(CONCATENATE("SDB\SDB_",A15,".pdf"),"2") -> 2 | G15: =IF(AJ15<>"",HYPERLINK(CONCATENATE("BAG\",AJ15,".pdf"),"2"),HYPERLINK(CONCATENATE("BAG\BAG_",A15,".pdf"),"2")) -> 2 | H15: =IF(ISERROR(FIND("GHS 01",$CA15)),"","●") | I15: =IF(ISERROR(FIND("GHS 02",$CA15)),"","●") | J15: =IF(ISERROR(FIND("GHS 03",$CA15)),"","●") | K15: =IF(ISERROR(FIND("GHS 04",$CA15)),"","●") | L15: =IF(ISERROR(FIND("GHS 05",$CA15)),"","●") | M15: =IF(ISERROR(FIND("GHS 06",$CA15)),"","●") | N15: =IF(ISERROR(FIND("GHS 07",$CA15)),"","●") | O15: =IF(ISERROR(FIND("GHS 08",$CA15)),"","●") | P15: =IF(ISERROR(FIND("GHS 09",$CA15)),"","●") | Q15: =IF(ISERROR(FIND("Achtung",$CA15)),"","A") | R15: =IF(ISERROR(FIND("Gefahr",$CA15)),"","G") | V15: =HYPERLINK(CONCATENATE("Bilder\",A15,".jpg"),"y") -> y | AG15: Abteilungsleiter | AN15: =HYPERLINK(CONCATENATE("TDB\TDB_",A15,".pdf"),"2") -> 2 | AQ15: Dose | AR15: 270 | AS15: ml | AU15: =IF(AS15="","",(IF(AS15="ml",(AR15/1000)*AT15,IF(AS15="Liter",AR15*AT15,IF(AS15="g",(AR15/1000)*AT15,IF(AS15="kg",AR15*AT15)))))) -> 0 | AV15: =IF(AS15="","",(IF(AS15="ml","Liter",IF(AS15="Liter","Liter",IF(AS15="g","kg",IF(AS15="kg","kg")))))) -> Liter | AY15: =IFERROR(VLOOKUP($AX15,Zusammenlagerung!$A$3:$AA$28,2,FALSE),"") | AZ15: =IFERROR(VLOOKUP($AX15,Zusammenlagerung!$A$3:$AA$28,3,FALSE),"") | BA15: =IFERROR(VLOOKUP($AX15,Zusammenlagerung!$A$3:$AA$28,4,FALSE),"") | BB15: =IFERROR(VLOOKUP($AX15,Zusammenlagerung!$A$3:$AA$28,5,FALSE),"") | BC15: =IFERROR(VLOOKUP($AX15,Zusammenlagerung!$A$3:$AA$28,6,FALSE),"") | BD15: =IFERROR(VLOOKUP($AX15,Zusammenlagerung!$A$3:$AA$28,7,FALSE),"") | BE15: =IFERROR(VLOOKUP($AX15,Zusammenlagerung!$A$3:$AA$28,8,FALSE),"") | BF15: =IFERROR(VLOOKUP($AX15,Zusammenlagerung!$A$3:$AA$28,9,FALSE),"") | BG15: =IFERROR(VLOOKUP($AX15,Zusammenlagerung!$A$3:$AA$28,10,FALSE),"") | BH15: =IFERROR(VLOOKUP($AX15,Zusammenlagerung!$A$3:$AA$28,11,FALSE),"") | BI15: =IFERROR(VLOOKUP($AX15,Zusammenlagerung!$A$3:$AA$28,12,FALSE),"") | BJ15: =IFERROR(VLOOKUP($AX15,Zusammenlagerung!$A$3:$AA$28,13,FALSE),"") | BK15: =IFERROR(VLOOKUP($AX15,Zusammenlagerung!$A$3:$AA$28,14,FALSE),"") | BL15: =IFERROR(VLOOKUP($AX15,Zusammenlagerung!$A$3:$AA$28,15,FALSE),"") | BM15: =IFERROR(VLOOKUP($AX15,Zusammenlagerung!$A$3:$AA$28,16,FALSE),"") | BN15: =IFERROR(VLOOKUP($AX15,Zusammenlagerung!$A$3:$AA$28,17,FALSE),"") | BO15: =IFERROR(VLOOKUP($AX15,Zusammenlagerung!$A$3:$AA$28,18,FALSE),"") | BP15: =IFERROR(VLOOKUP($AX15,Zusammenlagerung!$A$3:$AA$28,19,FALSE),"") | BQ15: =IFERROR(VLOOKUP($AX15,Zusammenlagerung!$A$3:$AA$28,20,FALSE),"") | BR15: =IFERROR(VLOOKUP($AX15,Zusammenlagerung!$A$3:$AA$28,21,FALSE),"") | BT15: =IFERROR(VLOOKUP($AX15,Zusammenlagerung!$A$3:$AA$28,23,FALSE),"") | BU15: =IFERROR(VLOOKUP($AX15,Zusammenlagerung!$A$3:$AA$28,24,FALSE),"") | BV15: =IFERROR(VLOOKUP($AX15,Zusammenlagerung!$A$3:$AA$28,25,FALSE),"") | BW15: =IFERROR(VLOOKUP($AX15,Zusammenlagerung!$A$3:$AA$28,26,FALSE),"") | BX15: =IFERROR(VLOOKUP($AX15,Zusammenlagerung!$A$3:$AA$28,27,FALSE),"") | BY15: =IF(CB15<>"",(IF(COUNTIFS(CB15,"*H220*")>0,"Liter",(IF(COUNTIFS(CB15,"*H221*")>0,"Liter",IF(COUNTIFS(CB15,"*H270*")>0,"Liter",IF(COUNTIFS(CB15,"*H280*")>0,"Liter",IF(COUNTIFS(CB15,"*H281*")>0,"Liter","kg"))))))),"") | CO15: 20 | CX15: {=INDEX(Einatmen!$A$21:$A$26,MATCH(CV15&CW15,Einatmen!$C$21:$C$26&Einatmen!$B$21:$B$26,0))} -> #N/A | CZ15: {=INDEX(Einatmen!$A$38:$A$49,MATCH(CV15&CY15,Einatmen!$C$38:$C$49&Einatmen!$B$38:$B$49,0))} -> #N/A | DA15: {=INDEX(Einatmen!$D$52:$D$159,MATCH(CU15&CX15&CZ15&CV15,Einatmen!$A$52:$A$159&Einatmen!$B$52:$B$159&Einatmen!$C$52:$C$159&Einatmen!$E$52:$E$159,0))} -> #N/A | DC15: =IF(ISNA(DA15),"",(IF(DB15="","",(HYPERLINK(CONCATENATE("Schutzleitfäden\",DB15,".pdf"),"1"))))) | DD15: =IFERROR(VLOOKUP(DB15,Schutzleitfäden!$A$3:$C$46,3,FALSE),"") | DH15: =IF(DG15=Haut!$A$12,Haut!$B$12,(IF(DG15=Haut!$A$13,Haut!$B$13,""))) | DJ15: =IF(DI15=Haut!$A$18,Haut!$C$18,(IF(DI15=Haut!$A$19,Haut!$C$19,""))) | DK15: {=INDEX(Haut!$D$22:$D$45,MATCH(DF15&DH15&DJ15,Haut!$A$22:$A$45&Haut!$B$22:$B$45&Haut!$C$22:$C$45,0))} -> #N/A | DL15: =IF(ISNA(DK15),"",(IF(DK15=Haut!$D$49,Haut!$E$49,(IF(DK15=Haut!$D$50,Haut!$E$50,(IF(DK15=Haut!$D$51,Haut!$E$51,(IF(DK15=Haut!$D$52,Haut!$E$52,(IF(DK15=Haut!$D$53,Haut!$E$53,""))))))))))) | DM15: =IF(ISNA(DK15),"",(HYPERLINK(CONCATENATE("Schutzleitfäden\",DL15,".pdf"),"1"))) | DN15: =IFERROR(VLOOKUP(DL15,Schutzleitfäden!$A$3:$C$46,3,FALSE),"") | DQ15: =CV15 -> 0 | DR15: =CW15 -> 0 | DS15: {=INDEX(Brand_EX!$A$15:$A$20,MATCH(DQ15&DR15,Brand_EX!$C$15:$C$20&Brand_EX!$B$15:$B$20,0))} -> #N/A | DT15: =CY15 -> 0 | DU15: {=INDEX(Brand_EX!$A$31:$A$41,MATCH(DQ15&DT15,Brand_EX!$C$31:$C$41&Brand_EX!$B$31:$B$41,0))} -> #N/A | DV15: {=INDEX(Brand_EX!$D$44:$D$133,MATCH(DP15&DS15&DU15&DQ15,Brand_EX!$A$44:$A$133&Brand_EX!$B$44:$B$133&Brand_EX!$C$44:$C$133&Brand_EX!$E$44:$E$133,0))} -> #N/A | DX15: =IF(ISNA(DV15),"",(IF(DW15="","",(HYPERLINK(CONCATENATE("Schutzleitfäden\",DW15,".pdf"),"1"))))) | DY15: =IFERROR(VLOOKUP(DW15,Schutzleitfäden!$A$3:$C$46,3,FALSE),"") | EA15: Die Möglichkeit zur Substitution des Produktes ist zu prüfen. | EJ15: =IF(EM15="Kat. 1A","ja",IF(EM15="Kat. 1B","ja",IF(ER15="Kat. 1A","ja",IF(ER15="Kat. 1B","ja",IF(EW15="Kat. 1A","ja",IF(EW15="Kat. 1B","ja","nein")))))) -> nein | EO15: =VLOOKUP(EN15,Daten!$M$2:$N$18,2,FALSE) -> #N/A | EP15: - | EQ15: 0 | ER15: - | ES15: keine | ET15: =VLOOKUP(ES15,Daten!$M$2:$N$18,2,FALSE) -> entfällt | EU15: - | EV15: 0 | EW15: - | EX15: keine | EY15: =VLOOKUP(EX15,Daten!$M$2:$N$18,2,FALSE) -> entfällt | FB15: =IF(ISERROR(VLOOKUP(FA15,Entsorgung,2,FALSE)),"",VLOOKUP(FA15,Entsorgung,2,FALSE)) | FD15: =IF(ISERROR(VLOOKUP(FC15,Entsorgung,2,FALSE)),"",VLOOKUP(FC15,Entsorgung,2,FALSE)) | FF15: =IF(ISERROR(VLOOKUP(FE15,Entsorgung,2,FALSE)),"",VLOOKUP(FE15,Entsorgung,2,FALSE)) | FH15: Chemikalien-Schutzhandschuhe | FI15: EN 374 | FN15: Dichtschließende Schutzbrille mit Seitenschutz | FO15: EN 166 | FP15: (nicht definiert) | FS15: (nicht definiert) | FX15: =IF(ISERROR(VLOOKUP(FW15,Gefahrgut,2,FALSE)),"",VLOOKUP(FW15,Gefahrgut,2,FALSE)) | FY15: =IF(ISERROR(VLOOKUP(FW15,Gefahrgut,3,FALSE)),"",VLOOKUP(FW15,Gefahrgut,3,FALSE)) | FZ15: =IF(ISERROR(VLOOKUP(FW15,Gefahrgut,4,FALSE)),"",VLOOKUP(FW15,Gefahrgut,4,FALSE))
