Workbook
Name Bereich: [1]Daten!$C$2:$C$40
Name Deckblatt_Kundennr: [2]Start!$B$20:$B$64
Name F_Auswahl: Daten!#REF!
Name Firma: [1]Daten!$A$2
Name Firma2: [1]Daten!$A$3
Name Gefährdungsfaktoren_Nummern: Daten!$A$2:$A$56
Name Handlungsbedarf: Daten!$I$2:$I$4
Name Jahr: Daten!#REF!
Name Kurzbeschreibung_Deckblatt: [2]Start!$B$68:$B$85
Name P_Auswahl: Daten!#REF!
Name Realisierung: Daten!#REF!
Name RLT_Kaeltemittel: [1]Daten!$H$2:$H$15
Name S_Auswahl: Daten!#REF!
Name Standort: [1]Daten!$B$2:$B$10
Name Status: [1]Daten!$G$2:$G$4
Name STOP: Daten!#REF!
Name Zuständigkeiten: #REF!

Sheet Übersicht GBU
A1: Übersicht der Gefährdungsbeurteilungen für Gefahrstoffe nach § 6 GefStoffV
A2: OTH Oberflächentechnik Hagen GmbH & Co. KG | K2: Filter
A3: SDB | B3: SDB öffnen | C3: GBU öffnen | D3: Produktbezeichnung / Handelsname | E3: Hersteller / Lieferant | F3: Sicherheitsdatenblatt vom | G3: Zustandsform | H3: Farbe | I3: Stoff / Gemisch | J3: Einsatzweck / interne Verwendung | K3: Kennzeichnung gemäß CLP-VO (EG) 1272/2008 | L3: H-Sätze: Physikalische Gefahren | M3: H-Sätze: Gesundheitsgefahren | N3: H-Sätze: Umweltgefahren | O3: H-Sätze: EUH | P3: P-Sätze: Allgemeines | Q3: P-Sätze: Prävention | R3: P-Sätze: Reaktion | S3: P-Sätze: Aufbewahrung | T3: P-Sätze: Entsorgung | U3: AGW | V3: Wassergefährdungsklasse (WGK) | W3: Tätigkeiten mit geringer Gefährdung (TRGS 400) | X3: Maßnahmenreihe EMGK "Einatmen" | Y3: Maßnahmenreihe EMGK "Einatmen" Bezeichnung | Z3: Maßnahmenreihe EMGK "Hautkontakt" | AA3: Maßnahmenreihe EMGK "Hautkontakt" Bezeichnung | AB3: Maßnahmenreihe EMGK "Brand und Explosion" | AC3: Maßnahmenreihe EMGK "Brand und Explosion" Bezeichnung | AD3: CMR1_a | AE3: CMR1_b | AF3: CMR1_c | AG3: CMR1_d | AH3: CMR1_e | AI3: CMR2_a | AJ3: CMR2_b | AK3: CMR2_c | AL3: CMR2_d | AM3: CMR2_e | AN3: CMR3_a | AO3: CMR3_b | AP3: CMR3_c | AQ3: CMR3_d | AR3: CMR3_e | AS3: Flammpunkt | AT3: explosive Eigen-schaften | AU3: UEG [Vol.-%] | AV3: OEG [Vol.-%] | AW3: Substitution_1
A4: 001 | B4: =HYPERLINK(CONCATENATE("..\SDB\SDB_",A4,".pdf"),"2") -> 2 | C4: =HYPERLINK("#"&CONCATENATE(A4,"!B1"),"2") -> 2 | D4: Steinex 22 | E4: Alufinish GmbH & Co. KG | F4: 45839 | G4: Flüssigkeit | H4: farblos | I4: Gemisch | J4: Beizen | K4: nicht als gefährlich eingestuft | L4: - | M4: - | N4: - | O4: EUH208 | P4: - | Q4: - | R4: - | S4: - | T4: - | U4: - | V4: 1 | W4: Ja, da keine gefährlichen Eigenschaften vorliegen. | X4: Schutzleitfaden-100 | Y4: Freie Lüftung | Z4: Schutzleitfaden-120 | AA4: Organisations- und Hygienemaßnahmen "Haut" | AB4: Schutzleitfaden-PC170 | AC4: Brandschutzmaßnahmen | AD4: - | AE4: 0 | AF4: - | AG4: keine | AH4: entfällt | AI4: - | AJ4: 0 | AK4: - | AL4: keine | AM4: entfällt | AN4: - | AO4: 0 | AP4: - | AQ4: keine | AR4: entfällt | AS4: - | AW4: Substitutionen sind im Galvanikbereich nicht zielführend (vgl. ASA vom 05.05.2025)
A5: 002 | B5: =HYPERLINK(CONCATENATE("..\SDB\SDB_",A5,".pdf"),"2") -> 2 | C5: =HYPERLINK("#"&CONCATENATE(A5,"!B1"),"2") -> 2 | D5: Alfideox 82/3 | E5: Alufinish GmbH & Co. KG | F5: 45251 | G5: Flüssigkeit | H5: farblos | I5: Gemisch | J5: Beizen | K5: GHS 05, GHS 06, Gefahr | L5: H290 | M5: H301, H310, H314, H331 | N5: - | O5: - | P5: - | Q5: P260, P280, | R5: P301+P310, P303+P361+P353, P305+P351+P338 | S5: - | T5: - | U5: Schwefelsäure, Hydrogenfluorid, | V5: 2 | W5: Nein, da die Einstufung H314 besteht und ein Hautkontakt nicht ausgeschlossen werden kann. | X5: Schutzleitfaden-300 | Y5: Geschlossenes System | Z5: Gefährdungsbeurteilung | AA5: siehe gefahrstoffspezifische Gefährdungsbeurteilung | AB5: Schutzleitfaden-PC270 | AC5: Grundanforderungen bei erhöhter Brandgefährdung | AD5: - | AE5: 0 | AF5: - | AG5: keine | AH5: entfällt | AI5: - | AJ5: 0 | AK5: - | AL5: keine | AM5: entfällt | AN5: - | AO5: 0 | AP5: - | AQ5: keine | AR5: entfällt | AS5: k.A | AW5: Substitutionen sind im Galvanikbereich nicht zielführend (vgl. ASA vom 05.05.2025)
A6: 003 | B6: =HYPERLINK(CONCATENATE("..\SDB\SDB_",A6,".pdf"),"2") -> 2 | C6: =HYPERLINK("#"&CONCATENATE(A6,"!B1"),"2") -> 2 | D6: Alfiflex 450 | E6: Alufinish GmbH & Co. KG | F6: 45140 | G6: Flüssigkeit | H6: farblos | I6: Gemisch | J6: Beizen | K6: GHS 05, Gefahr | L6: H290 | M6: H314 | N6: - | O6: - | P6: - | Q6: P260, P280, | R6: P310, P303+P361+P353, P305+P351+P338 | S6: - | T6: - | U6: Phosphorsäure, Schwefelsäure | V6: 1 | W6: Nein, da die Einstufung H314 besteht und ein Hautkontakt nicht ausgeschlossen werden kann. | X6: Schutzleitfaden-300 | Y6: Geschlossenes System | Z6: Gefährdungsbeurteilung | AA6: siehe gefahrstoffspezifische Gefährdungsbeurteilung | AB6: Schutzleitfaden-PC270 | AC6: Grundanforderungen bei erhöhter Brandgefährdung | AD6: - | AE6: 0 | AF6: - | AG6: keine | AH6: entfällt | AI6: - | AJ6: 0 | AK6: - | AL6: keine | AM6: entfällt | AN6: - | AO6: 0 | AP6: - | AQ6: keine | AR6: entfällt | AS6: k.A | AW6: Substitutionen sind im Galvanikbereich nicht zielführend (vgl. ASA vom 05.05.2025)
A7: 004 | B7: =HYPERLINK(CONCATENATE("..\SDB\SDB_",A7,".pdf"),"2") -> 2 | C7: =HYPERLINK("#"&CONCATENATE(A7,"!B1"),"2") -> 2 | D7: CHEMOPUR Trockensäure | E7: CHEMOPUR H. Brand GmbH | F7: 41695 | G7: Pulver | H7: weißlich | I7: 0 | J7: Beizen | K7: GHS 05, GHS 07, Gefahr | L7: - | M7: H302, H314 | N7: - | O7: - | P7: - | Q7: P260, P280, | R7: P310, P303+P361+P353, P305+P351+P338 , P304+P340, P301+P330+P331 | S7: - | T7: - | U7: Natriumhydrogendifluorid, | V7: 1 | W7: Archiv / derzeit nicht in Verwendung | X7: Schutzleitfaden-300 | Y7: Geschlossenes System | Z7: Schutzleitfaden-250 | AA7: Erweiterter Maßnahmenbedarf „Haut“ | AB7: Schutzleitfaden-PC270 | AC7: Grundanforderungen bei erhöhter Brandgefährdung | AD7: 0 | AE7: 0 | AF7: 0 | AG7: 0 | AH7: #N/A | AI7: - | AJ7: 0 | AK7: - | AL7: keine | AM7: entfällt | AN7: - | AO7: 0 | AP7: - | AQ7: keine | AR7: entfällt | AS7: - | AW7: Substitutionen sind im Galvanikbereich nicht zielführend (vgl. ASA vom 05.05.2025)
A8: 005 | B8: =HYPERLINK(CONCATENATE("..\SDB\SDB_",A8,".pdf"),"2") -> 2 | C8: =HYPERLINK("#"&CONCATENATE(A8,"!B1"),"2") -> 2 | D8: FerroChem KE | E8: ElpoChem AG | F8: 40290 | G8: Flüssigkeit | H8: 0 | I8: 0 | J8: Metalloberflächenbehandlung | K8: GHS 03, GHS 05, GHS 06, Gefahr | L8: H272 | M8: H301, H314 | N8: - | O8: - | P8: - | Q8: P210, P220, P221, P260, P264, P270, P280 | R8: P301+P310, P303+P361+P353, P305+P351+P338, P301+P330+P331, P304+P34, P310, P321, P330, P363, P370+P378 | S8: P405 | T8: - | U8: - | V8: 1 | W8: Archiv / derzeit nicht in Verwendung | X8: Schutzleitfaden-300 | Y8: Geschlossenes System | Z8: Schutzleitfaden-250 | AA8: Erweiterter Maßnahmenbedarf „Haut“ | AB8: Schutzleitfaden-PC370 | AC8: Hohe Brandschutzmaßnahmen - Grundanforderungen | AD8: 0 | AE8: 0 | AF8: 0 | AG8: 0 | AH8: #N/A | AI8: - | AJ8: 0 | AK8: - | AL8: keine | AM8: entfällt | AN8: - | AO8: 0 | AP8: - | AQ8: keine | AR8: entfällt | AS8: k.A | AW8: Substitutionen sind im Galvanikbereich nicht zielführend (vgl. ASA vom 05.05.2025)
A9: 006 | B9: =HYPERLINK(CONCATENATE("..\SDB\SDB_",A9,".pdf"),"2") -> 2 | C9: =HYPERLINK("#"&CONCATENATE(A9,"!B1"),"2") -> 2 | D9: Stahlbeize RSK | E9: ElpoChem AG | F9: 40071 | G9: Flüssigkeit | H9: gelb | I9: Gemisch | J9: Beizen | K9: GHS 05, Gefahr | L9: - | M9: H314 | N9: - | O9: - | P9: - | Q9: P260, P264, P280 | R9: P301+P330+P331, P303+P361+P353, P304+P340, P305+P351+P338, P310, P321, P363 | S9: P405 | T9: - | U9: Schwefelsäure | V9: 1 | W9: Nein, da die Einstufung H314 besteht und ein Hautkontakt nicht ausgeschlossen werden kann. | X9: Schutzleitfaden-200 | Y9: Örtliche Absaugung (Punktabsaugung) | Z9: Schutzleitfaden-250 | AA9: Erweiterter Maßnahmenbedarf „Haut“ | AB9: Schutzleitfaden-PC170 | AC9: Brandschutzmaßnahmen | AD9: - | AE9: 0 | AF9: - | AG9: keine | AH9: entfällt | AI9: - | AJ9: 0 | AK9: - | AL9: keine | AM9: entfällt | AN9: - | AO9: 0 | AP9: - | AQ9: keine | AR9: entfällt | AS9: - | AW9: Substitutionen sind im Galvanikbereich nicht zielführend (vgl. ASA vom 05.05.2025)
A10: 007 | B10: =HYPERLINK(CONCATENATE("..\SDB\SDB_",A10,".pdf"),"2") -> 2 | C10: =HYPERLINK("#"&CONCATENATE(A10,"!B1"),"2") -> 2 | D10: GLEITMO 625 | E10: Eissing GmbH / FUCHS LUBRITECH GmbH | F10: 44481 | G10: Flüssigkeit | H10: weiß | I10: Gemisch | J10: Gleitmittelfilm | K10: GHS 02, GHS 07, Achtung | L10: H226 | M10: H319 | N10: - | O10: EUH208 | P10: - | Q10: P210, P262 | R10: - | S10: - | T10: - | U10: Isopropanol | V10: 2 | W10: Nein, da gefährliche Einstufungen und Eigenschaften vorliegen (siehe EMKG). | X10: Schutzleitfaden-100 | Y10: Freie Lüftung | Z10: Schutzleitfaden-120 | AA10: Organisations- und Hygienemaßnahmen "Haut" | AB10: Schutzleitfaden-PC270 | AC10: Grundanforderungen bei erhöhter Brandgefährdung | AD10: - | AE10: 0 | AF10: - | AG10: keine | AH10: entfällt | AI10: - | AJ10: 0 | AK10: - | AL10: keine | AM10: entfällt | AN10: - | AO10: 0 | AP10: - | AQ10: keine | AR10: entfällt | AS10: 25 | AW10: Substitutionen sind im Galvanikbereich nicht zielführend (vgl. ASA vom 05.05.2025)
A11: 008 | B11: =HYPERLINK(CONCATENATE("..\SDB\SDB_",A11,".pdf"),"2") -> 2 | C11: =HYPERLINK("#"&CONCATENATE(A11,"!B1"),"2") -> 2 | D11: GLEITMO 2345 V | E11: Eissing GmbH / FUCHS LUBRITECH GmbH | F11: 42472 | G11: Flüssigkeit | H11: weiß | I11: Gemisch | J11: Gleitmittelfilm | K11: nicht als gefährlich eingestuft | L11: - | M11: - | N11: - | O11: - | P11: - | Q11: - | R11: - | S11: - | T11: - | U11: - | V11: 1 | W11: Ja, da keine gefährlichen Eigenschaften vorliegen. | X11: Schutzleitfaden-100 | Y11: Freie Lüftung | Z11: Schutzleitfaden-120 | AA11: Organisations- und Hygienemaßnahmen "Haut" | AB11: Schutzleitfaden-PC170 | AC11: Brandschutzmaßnahmen | AD11: - | AE11: 0 | AF11: - | AG11: keine | AH11: entfällt | AI11: - | AJ11: 0 | AK11: - | AL11: keine | AM11: entfällt | AN11: - | AO11: 0 | AP11: - | AQ11: keine | AR11: entfällt | AS11: - | AW11: Substitutionen sind im Galvanikbereich nicht zielführend (vgl. ASA vom 05.05.2025)
A12: 009 | B12: =HYPERLINK(CONCATENATE("..\SDB\SDB_",A12,".pdf"),"2") -> 2 | C12: =HYPERLINK("#"&CONCATENATE(A12,"!B1"),"2") -> 2 | D12: GLEITMO 605 | E12: Eissing GmbH / FUCHS LUBRITECH GmbH | F12: 44900 | G12: Flüssigkeit | H12: gelblich | I12: Gemisch | J12: Gleitmittelfilm | K12: GHS 05, Gefahr | L12: - | M12: H318 | N12: - | O12: - | P12: - | Q12: P280 | R12: P305+P351+P338, P310 | S12: - | T12: - | U12: - | V12: 2 | W12: Nein, da gefährliche Einstufungen und Eigenschaften vorliegen (siehe EMKG). | X12: Schutzleitfaden-100 | Y12: Freie Lüftung | Z12: Schutzleitfaden-120 | AA12: Organisations- und Hygienemaßnahmen "Haut" | AB12: Schutzleitfaden-PC170 | AC12: Brandschutzmaßnahmen | AD12: - | AE12: 0 | AF12: - | AG12: keine | AH12: entfällt | AI12: - | AJ12: 0 | AK12: - | AL12: keine | AM12: entfällt | AN12: - | AO12: 0 | AP12: - | AQ12: keine | AR12: entfällt | AS12: - | AW12: Substitutionen sind im Galvanikbereich nicht zielführend (vgl. ASA vom 05.05.2025)
A13: 010 | B13: =HYPERLINK(CONCATENATE("..\SDB\SDB_",A13,".pdf"),"2") -> 2 | C13: =HYPERLINK("#"&CONCATENATE(A13,"!B1"),"2") -> 2 | D13: HESSOPAS BP-400 | E13: Dr. HESSE GmbH & Cie KG | F13: 43362 | G13: Flüssigkeit | H13: grün | I13: 0 | J13: Metalloberflächenbehandlung | K13: GHS 05, GHS 08, GHS 09, Gefahr | L13: - | M13: H314, H317, H334, H350i, H360f, H341, | N13: H410 | O13: - | P13: - | Q13: P201, P202, P260, | R13: P310, P321 | S13: P405 | T13: - | U13: Natriumhydrogendifluorid, | V13: 3 | W13: Archiv / derzeit nicht in Verwendung | X13: Beratung | Y13: siehe tätigkeitsspezifische Gefährdungsbeurteilung | Z13: Schutzleitfaden-250 | AA13: Erweiterter Maßnahmenbedarf „Haut“ | AB13: Schutzleitfaden-PC170 | AC13: Brandschutzmaßnahmen | AD13: 0 | AE13: 0 | AF13: 0 | AG13: 0 | AH13: #N/A | AI13: - | AJ13: 0 | AK13: - | AL13: keine | AM13: entfällt | AN13: - | AO13: 0 | AP13: - | AQ13: keine | AR13: entfällt | AS13: - | AW13: Substitutionen sind im Galvanikbereich nicht zielführend (vgl. ASA vom 05.05.2025)
A14: 011 | B14: =HYPERLINK(CONCATENATE("..\SDB\SDB_",A14,".pdf"),"2") -> 2 | C14: =HYPERLINK("#"&CONCATENATE(A14,"!B1"),"2") -> 2 | D14: HESSONIC MP-4 Teil A | E14: Dr. HESSE GmbH & Cie KG | F14: 42110 | G14: Flüssigkeit | H14: 0 | I14: 0 | J14: Metalloberflächenbehandlung | K14: GHS 08, GHS 09, Gefahr | L14: - | M14: H317, H334, H341, H350i, H360D, H372 | N14: H411 | O14: - | P14: - | Q14: P201, P202, P260, | R14: P314, P342+P311 | S14: P405 | T14: - | U14: DINATRIUMTETRABORATDECAHYDRAT | V14: 2 | W14: Archiv / derzeit nicht in Verwendung | X14: Beratung | Y14: siehe tätigkeitsspezifische Gefährdungsbeurteilung | Z14: Gefährdungsbeurteilung | AA14: siehe gefahrstoffspezifische Gefährdungsbeurteilung | AB14: Schutzleitfaden-PC170 | AC14: Brandschutzmaßnahmen | AD14: 0 | AE14: 0 | AF14: 0 | AG14: 0 | AH14: #N/A | AI14: - | AJ14: 0 | AK14: - | AL14: keine | AM14: entfällt | AN14: - | AO14: 0 | AP14: - | AQ14: keine | AR14: entfällt | AS14: - | AW14: Substitutionen sind im Galvanikbereich nicht zielführend (vgl. ASA vom 05.05.2025)
A15: 012 | B15: =HYPERLINK(CONCATENATE("..\SDB\SDB_",A15,".pdf"),"2") -> 2 | C15: =HYPERLINK("#"&CONCATENATE(A15,"!B1"),"2") -> 2 | D15: HESSONIC MP-4,Teil B | E15: Dr. HESSE GmbH & Cie KG | F15: 42110 | G15: Flüssigkeit | H15: grün | I15: 0 | J15: Metalloberflächenbehandlung | K15: GHS 05, GHS 08, GHS 09, Gefahr | L15: - | M15: H315, H317, H318, H334, H341, H350i, H360D, H372, | N15: H411 | O15: - | P15: - | Q15: P201, P202, P260, | R15: P310, P321 | S15: P405 | T15: - | U15: BORSÄURE | V15: 2 | W15: Archiv / derzeit nicht in Verwendung | X15: Beratung | Y15: siehe tätigkeitsspezifische Gefährdungsbeurteilung | Z15: Gefährdungsbeurteilung | AA15: siehe gefahrstoffspezifische Gefährdungsbeurteilung | AB15: Schutzleitfaden-PC170 | AC15: Brandschutzmaßnahmen | AD15: 0 | AE15: 0 | AF15: 0 | AG15: 0 | AH15: #N/A | AI15: - | AJ15: 0 | AK15: - | AL15: keine | AM15: entfällt | AN15: - | AO15: 0 | AP15: - | AQ15: keine | AR15: entfällt | AS15: - | AW15: Substitutionen sind im Galvanikbereich nicht zielführend (vgl. ASA vom 05.05.2025)
A16: 013 | B16: =HYPERLINK(CONCATENATE("..\SDB\SDB_",A16,".pdf"),"2") -> 2 | C16: =HYPERLINK("#"&CONCATENATE(A16,"!B1"),"2") -> 2 | D16: HESSONIC MP-4,Teil C | E16: Dr. HESSE GmbH & Cie KG | F16: 42110 | G16: Flüssigkeit | H16: farblos | I16: 0 | J16: Metalloberflächenbehandlung | K16: GHS 05, GHS 07, Gefahr | L16: - | M16: H314, H335 | N16: - | O16: - | P16: - | Q16: P260, P264 | R16: P310, P321 | S16: P405, P403+P233 | T16: - | U16: - | V16: 2 | W16: Archiv / derzeit nicht in Verwendung | X16: Schutzleitfaden-300 | Y16: Geschlossenes System | Z16: Schutzleitfaden-250 | AA16: Erweiterter Maßnahmenbedarf „Haut“ | AB16: Schutzleitfaden-PC170 | AC16: Brandschutzmaßnahmen | AD16: 0 | AE16: 0 | AF16: 0 | AG16: 0 | AH16: #N/A | AI16: - | AJ16: 0 | AK16: - | AL16: keine | AM16: entfällt | AN16: - | AO16: 0 | AP16: - | AQ16: keine | AR16: entfällt | AS16: - | AW16: Substitutionen sind im Galvanikbereich nicht zielführend (vgl. ASA vom 05.05.2025)
A17: 014 | B17: =HYPERLINK(CONCATENATE("..\SDB\SDB_",A17,".pdf"),"2") -> 2 | C17: =HYPERLINK("#"&CONCATENATE(A17,"!B1"),"2") -> 2 | D17: SUPRAGAL NOVA Träger AS 100 | E17: Dr. HESSE GmbH & Cie KG | F17: 42110 | G17: Flüssigkeit | H17: farblos | I17: 0 | J17: Metalloberflächenbehandlung | K17: nicht als gefährlich eingestuft | L17: - | M17: - | N17: - | O17: - | P17: - | Q17: - | R17: - | S17: - | T17: - | U17: - | V17: 1 | W17: Ja, da keine gefährlichen Eigenschaften vorliegen. | X17: Schutzleitfaden-100 | Y17: Freie Lüftung | Z17: Schutzleitfaden-120 | AA17: Organisations- und Hygienemaßnahmen "Haut" | AB17: Schutzleitfaden-PC170 | AC17: Brandschutzmaßnahmen | AD17: 0 | AE17: 0 | AF17: 0 | AG17: 0 | AH17: #N/A | AI17: - | AJ17: 0 | AK17: - | AL17: keine | AM17: entfällt | AN17: - | AO17: 0 | AP17: - | AQ17: keine | AR17: entfällt | AS17: - | AW17: Substitutionen sind im Galvanikbereich nicht zielführend (vgl. ASA vom 05.05.2025)
A18: 015 | B18: =HYPERLINK(CONCATENATE("..\SDB\SDB_",A18,".pdf"),"2") -> 2 | C18: =HYPERLINK("#"&CONCATENATE(A18,"!B1"),"2") -> 2 | D18: SUPRAGAL NOVA, Glanz 100 | E18: Dr. HESSE GmbH & Cie KG | F18: 42110 | G18: Flüssigkeit | H18: gelblich | I18: 0 | J18: Metalloberflächenbehandlung | K18: nicht als gefährlich eingestuft | L18: - | M18: - | N18: - | O18: - | P18: - | Q18: - | R18: - | S18: - | T18: - | U18: - | V18: 1 | W18: Ja, da keine gefährlichen Eigenschaften vorliegen. | X18: Schutzleitfaden-100 | Y18: Freie Lüftung | Z18: Schutzleitfaden-120 | AA18: Organisations- und Hygienemaßnahmen "Haut" | AB18: Schutzleitfaden-PC170 | AC18: Brandschutzmaßnahmen | AD18: 0 | AE18: 0 | AF18: 0 | AG18: 0 | AH18: #N/A | AI18: - | AJ18: 0 | AK18: - | AL18: keine | AM18: entfällt | AN18: - | AO18: 0 | AP18: - | AQ18: keine | AR18: entfällt | AS18: - | AW18: Substitutionen sind im Galvanikbereich nicht zielführend (vgl. ASA vom 05.05.2025)
A19: 016 | B19: =HYPERLINK(CONCATENATE("..\SDB\SDB_",A19,".pdf"),"2") -> 2 | C19: =HYPERLINK("#"&CONCATENATE(A19,"!B1"),"2") -> 2 | D19: SUPRAGAL NOVA Netzmittel WM 100 | E19: Dr. HESSE GmbH & Cie KG | F19: 42110 | G19: Flüssigkeit | H19: gelblich | I19: 0 | J19: Metalloberflächenbehandlung | K19: GHS 05, Gefahr | L19: - | M19: H315, H318 | N19: - | O19: 0 | P19: - | Q19: P264, P280 | R19: P310, P321, P305+P351+P338, P302+P352 | S19: 0 | T19: 0 | U19: - | V19: 2 | W19: Archiv / derzeit nicht in Verwendung | X19: Schutzleitfaden-200 | Y19: Örtliche Absaugung (Punktabsaugung) | Z19: Schutzleitfaden-120 | AA19: Organisations- und Hygienemaßnahmen "Haut" | AB19: Schutzleitfaden-PC170 | AC19: Brandschutzmaßnahmen | AD19: 0 | AE19: 0 | AF19: 0 | AG19: 0 | AH19: #N/A | AI19: - | AJ19: 0 | AK19: - | AL19: keine | AM19: entfällt | AN19: - | AO19: 0 | AP19: - | AQ19: keine | AR19: entfällt | AS19: 70 | AW19: Substitutionen sind im Galvanikbereich nicht zielführend (vgl. ASA vom 05.05.2025)
A20: 017 | B20: =HYPERLINK(CONCATENATE("..\SDB\SDB_",A20,".pdf"),"2") -> 2 | C20: =HYPERLINK("#"&CONCATENATE(A20,"!B1"),"2") -> 2 | D20: SUPRAGAL NOVA Einebner LC 100 | E20: Dr. HESSE GmbH & Cie KG | F20: 42110 | G20: Flüssigkeit | H20: farblos | I20: 0 | J20: Metalloberflächenbehandlung | K20: GHS 08, Gefahr | L20: - | M20: H350 | N20: - | O20: EUH208 | P20: - | Q20: P201, P202, P280, | R20: P308+P313 | S20: P405 | T20: - | U20: - | V20: 3 | W20: Archiv / derzeit nicht in Verwendung | X20: Beratung | Y20: siehe tätigkeitsspezifische Gefährdungsbeurteilung | Z20: Gefährdungsbeurteilung | AA20: siehe gefahrstoffspezifische Gefährdungsbeurteilung | AB20: Schutzleitfaden-PC170 | AC20: Brandschutzmaßnahmen | AD20: 0 | AE20: 0 | AF20: 0 | AG20: 0 | AH20: #N/A | AI20: - | AJ20: 0 | AK20: - | AL20: keine | AM20: entfällt | AN20: - | AO20: 0 | AP20: - | AQ20: keine | AR20: entfällt | AS20: 70 | AW20: Substitutionen sind im Galvanikbereich nicht zielführend (vgl. ASA vom 05.05.2025)
A21: 018 | B21: =HYPERLINK(CONCATENATE("..\SDB\SDB_",A21,".pdf"),"2") -> 2 | C21: =HYPERLINK("#"&CONCATENATE(A21,"!B1"),"2") -> 2 | D21: Entmetallisierung Ni/P EN Teil I | E21: Dr. HESSE GmbH & Cie KG | F21: 42110 | G21: Flüssigkeit | H21: gelblich | I21: 0 | J21: Metalloberflächenbehandlung | K21: GHS 07, Achtung | L21: - | M21: H317, H319 | N21: - | O21: - | P21: - | Q21: P261, P264, P272 | R21: P321, P333+P313, P337+P313 | S21: - | T21: - | U21: - | V21: 1 | W21: Archiv / derzeit nicht in Verwendung | X21: Schutzleitfaden-200 | Y21: Örtliche Absaugung (Punktabsaugung) | Z21: Schutzleitfaden-120 | AA21: Organisations- und Hygienemaßnahmen "Haut" | AB21: Schutzleitfaden-PC270 | AC21: Grundanforderungen bei erhöhter Brandgefährdung | AD21: 0 | AE21: 0 | AF21: 0 | AG21: 0 | AH21: #N/A | AI21: - | AJ21: 0 | AK21: - | AL21: keine | AM21: entfällt | AN21: - | AO21: 0 | AP21: - | AQ21: keine | AR21: entfällt | AS21: - | AW21: Substitutionen sind im Galvanikbereich nicht zielführend (vgl. ASA vom 05.05.2025)
A22: 019 | B22: =HYPERLINK(CONCATENATE("..\SDB\SDB_",A22,".pdf"),"2") -> 2 | C22: =HYPERLINK("#"&CONCATENATE(A22,"!B1"),"2") -> 2 | D22: Entmetallisierung Ni/P EN Teil II | E22: Dr. HESSE GmbH & Cie KG | F22: 42110 | G22: Feststoff | H22: weißlich | I22: 0 | J22: Metalloberflächenbehandlung | K22: GHS 07, Achtung | L22: - | M22: H302, H312, H332 | N22: H412 | O22: EUH032 | P22: - | Q22: P261, P264, P270 | R22: P310, P321, P330 | S22: - | T22: - | U22: - | V22: 1 | W22: Archiv / derzeit nicht in Verwendung | X22: Schutzleitfaden-200 | Y22: Örtliche Absaugung (Punktabsaugung) | Z22: Schutzleitfaden-120 | AA22: Organisations- und Hygienemaßnahmen "Haut" | AB22: Schutzleitfaden-PC270 | AC22: Grundanforderungen bei erhöhter Brandgefährdung | AD22: 0 | AE22: 0 | AF22: 0 | AG22: 0 | AH22: #N/A | AI22: - | AJ22: 0 | AK22: - | AL22: keine | AM22: entfällt | AN22: - | AO22: 0 | AP22: - | AQ22: keine | AR22: entfällt | AS22: 0 | AW22: Substitutionen sind im Galvanikbereich nicht zielführend (vgl. ASA vom 05.05.2025)
A23: 020 | B23: =HYPERLINK(CONCATENATE("..\SDB\SDB_",A23,".pdf"),"2") -> 2 | C23: =HYPERLINK("#"&CONCATENATE(A23,"!B1"),"2") -> 2 | D23: Entmetallisierung Ni/P EN Teil III | E23: Dr. HESSE GmbH & Cie KG | F23: 42110 | G23: Flüssigkeit | H23: gelblich | I23: 0 | J23: Metalloberflächenbehandlung | K23: GHS 05, GHS 07, GHS 08, Gefahr | L23: - | M23: H314, H317, H334, H302, H312 | N23: - | O23: - | P23: - | Q23: P260, P264, P270, | R23: P310, P321 | S23: P405 | T23: 0 | U23: - | V23: 2 | W23: Archiv / derzeit nicht in Verwendung | X23: Schutzleitfaden-300 | Y23: Geschlossenes System | Z23: Schutzleitfaden-250 | AA23: Erweiterter Maßnahmenbedarf „Haut“ | AB23: Schutzleitfaden-PC170 | AC23: Brandschutzmaßnahmen | AD23: 0 | AE23: 0 | AF23: 0 | AG23: 0 | AH23: #N/A | AI23: - | AJ23: 0 | AK23: - | AL23: keine | AM23: entfällt | AN23: - | AO23: 0 | AP23: - | AQ23: keine | AR23: entfällt | AS23: 75 | AW23: Substitutionen sind im Galvanikbereich nicht zielführend (vgl. ASA vom 05.05.2025)
A24: 021 | B24: =HYPERLINK(CONCATENATE("..\SDB\SDB_",A24,".pdf"),"2") -> 2 | C24: =HYPERLINK("#"&CONCATENATE(A24,"!B1"),"2") -> 2 | D24: Proseal Additiv Y | E24: KIESOW OBERFLÄCHENCHEMIE GmbH & Co. KG | F24: 45154 | G24: Flüssigkeit | H24: Dunkelgelb | I24: Gemisch | J24: Metalloberflächenbehandlung | K24: nicht als gefährlich eingestuft | L24: - | M24: - | N24: - | O24: EUH210 | P24: - | Q24: - | R24: - | S24: - | T24: - | U24: - | V24: nwg | W24: Ja, da keine gefährlichen Eigenschaften vorliegen. | X24: Schutzleitfaden-100 | Y24: Freie Lüftung | Z24: Schutzleitfaden-120 | AA24: Organisations- und Hygienemaßnahmen "Haut" | AB24: Schutzleitfaden-PC270 | AC24: Grundanforderungen bei erhöhter Brandgefährdung | AD24: - | AE24: 0 | AF24: - | AG24: keine | AH24: entfällt | AI24: - | AJ24: 0 | AK24: - | AL24: keine | AM24: entfällt | AN24: - | AO24: 0 | AP24: - | AQ24: keine | AR24: entfällt | AS24: - | AW24: Substitutionen sind im Galvanikbereich nicht zielführend (vgl. ASA vom 05.05.2025)
A25: 022 | B25: =HYPERLINK(CONCATENATE("..\SDB\SDB_",A25,".pdf"),"2") -> 2 | C25: =HYPERLINK("#"&CONCATENATE(A25,"!B1"),"2") -> 2 | D25: Proseal XZ 111 | E25: KIESOW OBERFLÄCHENCHEMIE GmbH & Co. KG | F25: 45278 | G25: Flüssigkeit | H25: dunkelgrün | I25: Gemisch | J25: Metalloberflächenbehandlung | K25: GHS 05, GHS 08, GHS 09, Gefahr | L25: - | M25: H314, H317, H334, H341, H350i, H360F | N25: H410 | O25: - | P25: - | Q25: P260 | R25: P303+P361+P353, P305+P351+P338, P310, P321, P362+P364 | S25: P405 | T25: P501 | U25: Salpetersäure 54%ig (2,5-10%), | V25: 3 | W25: Archiv / derzeit nicht in Verwendung | X25: Beratung | Y25: siehe tätigkeitsspezifische Gefährdungsbeurteilung | Z25: Gefährdungsbeurteilung | AA25: siehe gefahrstoffspezifische Gefährdungsbeurteilung | AB25: Schutzleitfaden-PC170 | AC25: Brandschutzmaßnahmen | AD25: Kobalt(II)-Sulfat | AE25: 2,5-5 | AF25: Kat. 1B | AG25: H350i | AH25: Kann bei Einatmen Krebs erzeugen. | AI25: Kobalt(II)-Sulfat | AJ25: 2,5-5 | AK25: Kat. 1B | AL25: H360F | AM25: Kann die Fruchtbarkeit beeinträchtigen. | AN25: Kobalt(II)-Sulfat | AO25: 2,5-5 | AP25: Kat. 2 | AQ25: H341 | AR25: Kann vermutlich genetische Defekte verursachen. | AS25: - | AW25: Substitutionen sind im Galvanikbereich nicht zielführend (vgl. ASA vom 05.05.2025)
A26: 023 | B26: =HYPERLINK(CONCATENATE("..\SDB\SDB_",A26,".pdf"),"2") -> 2 | C26: =HYPERLINK("#"&CONCATENATE(A26,"!B1"),"2") -> 2 | D26: SURFACLEAN V 149 | E26: KIESOW OBERFLÄCHENCHEMIE GmbH & Co. KG | F26: 44259 | G26: Flüssigkeit | H26: hellgelb | I26: Gemisch | J26: Metalloberflächenbehandlung | K26: GHS 05, GHS 07, Gefahr | L26: - | M26: H302, H314. H318 | N26: - | O26: - | P26: - | Q26: P260 | R26: P303+P361+P353, P305+P351+P338, P310, P321 | S26: - | T26: - | U26: - | V26: 1 | W26: Nein, da die Einstufung H314 besteht und ein Hautkontakt nicht ausgeschlossen werden kann. | X26: Schutzleitfaden-300 | Y26: Geschlossenes System | Z26: Gefährdungsbeurteilung | AA26: siehe gefahrstoffspezifische Gefährdungsbeurteilung | AB26: Schutzleitfaden-PC170 | AC26: Brandschutzmaßnahmen | AD26: - | AE26: 0 | AF26: - | AG26: keine | AH26: entfällt | AI26: - | AJ26: 0 | AK26: - | AL26: keine | AM26: entfällt | AN26: - | AO26: 0 | AP26: - | AQ26: keine | AR26: entfällt | AS26: - | AW26: Substitutionen sind im Galvanikbereich nicht zielführend (vgl. ASA vom 05.05.2025)
A27: 024 | B27: =HYPERLINK(CONCATENATE("..\SDB\SDB_",A27,".pdf"),"2") -> 2 | C27: =HYPERLINK("#"&CONCATENATE(A27,"!B1"),"2") -> 2 | D27: SURFACLEAN N 958 | E27: KIESOW OBERFLÄCHENCHEMIE GmbH & Co. KG | F27: 45608 | G27: Flüssigkeit | H27: dunkelgelb | I27: Gemisch | J27: Metalloberflächenbehandlung | K27: GHS 05, GHS 07, Gefahr | L27: - | M27: H302, H315, H318 | N27: - | O27: - | P27: - | Q27: P280 | R27: P305+P351+P338, P310, P321, 330, P362+P364 | S27: 0 | T27: P501 | U27: - | V27: 2 | W27: Nein, da gefährliche Einstufungen und Eigenschaften vorliegen (siehe EMKG). | X27: Schutzleitfaden-200 | Y27: Örtliche Absaugung (Punktabsaugung) | Z27: Schutzleitfaden-120 | AA27: Organisations- und Hygienemaßnahmen "Haut" | AB27: Schutzleitfaden-PC170 | AC27: Brandschutzmaßnahmen | AD27: - | AE27: 0 | AF27: - | AG27: keine | AH27: entfällt | AI27: - | AJ27: 0 | AK27: - | AL27: keine | AM27: entfällt | AN27: - | AO27: 0 | AP27: - | AQ27: keine | AR27: entfällt | AS27: - | AW27: Substitutionen sind im Galvanikbereich nicht zielführend (vgl. ASA vom 05.05.2025)
A28: 025 | B28: =HYPERLINK(CONCATENATE("..\SDB\SDB_",A28,".pdf"),"2") -> 2 | C28: =HYPERLINK("#"&CONCATENATE(A28,"!B1"),"2") -> 2 | D28: SUPRAGAL NOVA Netzmittel WA 100 | E28: Dr. HESSE GmbH & Cie KG | F28: 42110 | G28: Flüssigkeit | H28: 0 | I28: 0 | J28: Metalloberflächenbehandlung | K28: 0 | L28: 0 | M28: H315, 318 | N28: 0 | O28: 0 | P28: 0 | Q28: 0 | R28: 0 | S28: 0 | T28: 0 | U28: 0 | V28: 0 | W28: Archiv / derzeit nicht in Verwendung | X28: 0 | Z28: Schutzleitfaden-120 | AA28: Organisations- und Hygienemaßnahmen "Haut" | AB28: 0 | AD28: 0 | AE28: 0 | AF28: 0 | AG28: 0 | AH28: #N/A | AI28: - | AJ28: 0 | AK28: - | AL28: keine | AM28: entfällt | AN28: - | AO28: 0 | AP28: - | AQ28: keine | AR28: entfällt | AS28: 0 | AW28: Substitutionen sind im Galvanikbereich nicht zielführend (vgl. ASA vom 05.05.2025)
A29: 026 | B29: =HYPERLINK(CONCATENATE("..\SDB\SDB_",A29,".pdf"),"2") -> 2 | C29: =HYPERLINK("#"&CONCATENATE(A29,"!B1"),"2") -> 2 | D29: Ammoniumpufferlösung für die Komplexometrie PH 10 | E29: Merck KGaA | F29: 43353 | G29: Flüssigkeit | H29: farblos | I29: Gemisch | J29: Chemische Analytik | K29: GHS 05, GHS 07, Gefahr | L29: - | M29: H314, H335 | N29: - | O29: - | P29: - | Q29: P280 | R29: P301 + P330 + P331, P305 + P351 + P338, P308 + P310 | S29: - | T29: - | U29: Ammoniak in wässriger Lösung, Ammoniumchlorid | V29: 2 | W29: Ja, da nur geringe Stoffmengen verwendet werden (für analytische Zwecke, Proben, Kleinarbeiten) | X29: Schutzleitfaden-200 | Y29: Örtliche Absaugung (Punktabsaugung) | Z29: Gefährdungsbeurteilung | AA29: siehe gefahrstoffspezifische Gefährdungsbeurteilung | AB29: Schutzleitfaden-PC170 | AC29: Brandschutzmaßnahmen | AD29: - | AE29: 0 | AF29: - | AG29: keine | AH29: entfällt | AI29: - | AJ29: 0 | AK29: - | AL29: keine | AM29: entfällt | AN29: - | AO29: 0 | AP29: - | AQ29: keine | AR29: entfällt | AS29: - | AW29: Substitutionen sind im Galvanikbereich nicht zielführend (vgl. ASA vom 05.05.2025)
A30: 027 | B30: =HYPERLINK(CONCATENATE("..\SDB\SDB_",A30,".pdf"),"2") -> 2 | C30: =HYPERLINK("#"&CONCATENATE(A30,"!B1"),"2") -> 2 | D30: BROMKRESOLPURPUR | E30: Carl Roth GmbH + Co KG | F30: 45355 | G30: Feststoff | H30: violett | I30: Stoff | J30: Chemische Analytik | K30: nicht als gefährlich eingestuft | L30: - | M30: - | N30: - | O30: - | P30: - | Q30: - | R30: - | S30: - | T30: - | U30: - | V30: 1 | W30: Ja, da keine gefährlichen Eigenschaften vorliegen. | X30: Schutzleitfaden-100 | Y30: Freie Lüftung | Z30: Schutzleitfaden-120 | AA30: Organisations- und Hygienemaßnahmen "Haut" | AB30: Schutzleitfaden-PC170 | AC30: Brandschutzmaßnahmen | AD30: - | AE30: 0 | AF30: - | AG30: keine | AH30: entfällt | AI30: - | AJ30: 0 | AK30: - | AL30: keine | AM30: entfällt | AN30: - | AO30: 0 | AP30: - | AQ30: keine | AR30: entfällt | AS30: - | AW30: Substitutionen sind im Galvanikbereich nicht zielführend (vgl. ASA vom 05.05.2025)
A31: 028 | B31: =HYPERLINK(CONCATENATE("..\SDB\SDB_",A31,".pdf"),"2") -> 2 | C31: =HYPERLINK("#"&CONCATENATE(A31,"!B1"),"2") -> 2 | D31: Heizöl | E31: n. n. / diverse | F31: 44070 | G31: Flüssigkeit | H31: rot | I31: Gemisch | J31: Heizung | K31: GHS 02, GHS 07, GHS 08, GHS 09, Gefahr | L31: H226 | M31: H304, H315, H332, H351, H373 | N31: H411 | O31: 0 | P31: P102 | Q31: P210, P260, P273, P280 | R31: P301 + P310, P331 | S31: P403 + P233 | T31: P501 | U31: - | V31: 2 | W31: Nein, da gefährliche Einstufungen und Eigenschaften vorliegen (siehe EMKG). | X31: 0 | Z31: Schutzleitfaden-120 | AA31: Organisations- und Hygienemaßnahmen "Haut" | AB31: 0 | AD31: Brennstoffe, Diesel- | AE31: 100 | AF31: Kat. 2 | AG31: H351 | AH31: Kann vermutlich Krebs erzeugen. | AI31: - | AJ31: 0 | AK31: - | AL31: keine | AM31: entfällt | AN31: - | AO31: 0 | AP31: - | AQ31: keine | AR31: entfällt | AS31: 55 | AW31: Substitutionen sind im Galvanikbereich nicht zielführend (vgl. ASA vom 05.05.2025)
A32: 029 | B32: =HYPERLINK(CONCATENATE("..\SDB\SDB_",A32,".pdf"),"2") -> 2 | C32: =HYPERLINK("#"&CONCATENATE(A32,"!B1"),"2") -> 2 | D32: di-Kaliumoxalat-Monohydrat | E32: Carl Roth GmbH + Co KG | F32: 45352 | G32: Feststoff | H32: weiß | I32: Stoff | J32: Chemische Analytik | K32: GHS 07, Achtung | L32: - | M32: H302+H312 | N32: - | O32: - | P32: - | Q32: P270, P280 | R32: P302+P352 | S32: - | T32: - | U32: Staub | V32: nwg | W32: Ja, da nur geringe Stoffmengen verwendet werden (für analytische Zwecke, Proben, Kleinarbeiten) | X32: Schutzleitfaden-100 | Y32: Freie Lüftung | Z32: Schutzleitfaden-120 | AA32: Organisations- und Hygienemaßnahmen "Haut" | AB32: Schutzleitfaden-PC170 | AC32: Brandschutzmaßnahmen | AD32: - | AE32: 0 | AF32: - | AG32: keine | AH32: entfällt | AI32: - | AJ32: 0 | AK32: - | AL32: keine | AM32: entfällt | AN32: - | AO32: 0 | AP32: - | AQ32: keine | AR32: entfällt | AS32: - | AW32: Substitutionen sind im Galvanikbereich nicht zielführend (vgl. ASA vom 05.05.2025)
A33: 030 | B33: =HYPERLINK(CONCATENATE("..\SDB\SDB_",A33,".pdf"),"2") -> 2 | C33: =HYPERLINK("#"&CONCATENATE(A33,"!B1"),"2") -> 2 | D33: Dimethylgelb Indikatorlösung 0,2 % in Ethanol, vergällt | E33: Carl Roth GmbH + Co KG | F33: 44658 | G33: Flüssigkeit | H33: gelb | I33: Gemisch | J33: Chemische Analytik | K33: GHS 02, GHS 07, Gefahr | L33: H225 | M33: H319 | N33: - | O33: - | P33: - | Q33: P210 | R33: P305+P351+P338 | S33: P403+P233 | T33: - | U33: Ethanol | V33: nwg | W33: Ja, da nur geringe Stoffmengen verwendet werden (für analytische Zwecke, Proben, Kleinarbeiten) | X33: Schutzleitfaden-100 | Y33: Freie Lüftung | Z33: Schutzleitfaden-120 | AA33: Organisations- und Hygienemaßnahmen "Haut" | AB33: Schutzleitfaden-PC170 | AC33: Brandschutzmaßnahmen | AD33: Dimethylgelb | AE33: < 2,5 | AF33: Kat. 2 | AG33: H351 | AH33: Kann vermutlich Krebs erzeugen. | AI33: - | AJ33: 0 | AK33: - | AL33: keine | AM33: entfällt | AN33: - | AO33: 0 | AP33: - | AQ33: keine | AR33: entfällt | AS33: 12 | AW33: Substitutionen sind im Galvanikbereich nicht zielführend (vgl. ASA vom 05.05.2025)
A34: 031 | B34: =HYPERLINK(CONCATENATE("..\SDB\SDB_",A34,".pdf"),"2") -> 2 | C34: =HYPERLINK("#"&CONCATENATE(A34,"!B1"),"2") -> 2 | D34: Eriochromschwarz T | E34: Carl Roth GmbH + Co KG | F34: 44046 | G34: Pulver | H34: schwarz | I34: Stoff | J34: Chemische Analytik | K34: GHS 07, GHS 09, Achtung | L34: - | M34: H319 | N34: H411 | O34: - | P34: - | Q34: P273, P280 | R34: P305+P351+P338 | S34: - | T34: - | U34: Allgemeiner Staubgrenzwert, Alveolengängige Fraktion | V34: 2 | W34: Ja, da nur geringe Stoffmengen verwendet werden (für analytische Zwecke, Proben, Kleinarbeiten) | X34: Schutzleitfaden-100 | Y34: Freie Lüftung | Z34: Schutzleitfaden-120 | AA34: Organisations- und Hygienemaßnahmen "Haut" | AB34: Schutzleitfaden-PC170 | AC34: Brandschutzmaßnahmen | AD34: - | AE34: 0 | AF34: - | AG34: keine | AH34: entfällt | AI34: - | AJ34: 0 | AK34: - | AL34: keine | AM34: entfällt | AN34: - | AO34: 0 | AP34: - | AQ34: keine | AR34: entfällt | AS34: - | AW34: Substitutionen sind im Galvanikbereich nicht zielführend (vgl. ASA vom 05.05.2025)
A35: 032 | B35: =HYPERLINK(CONCATENATE("..\SDB\SDB_",A35,".pdf"),"2") -> 2 | C35: =HYPERLINK("#"&CONCATENATE(A35,"!B1"),"2") -> 2 | D35: Ethanol ROTISOLV® Pestilyse®plus ≥99,9 % | E35: Carl Roth GmbH + Co KG | F35: 45355 | G35: Flüssigkeit | H35: farblos | I35: Stoff | J35: Chemische Analytik | K35: GHS 02, GHS 07, Gefahr | L35: H225 | M35: H319 | N35: - | O35: - | P35: - | Q35: P210, P233 | R35: P305+P351+P338 | S35: - | T35: - | U35: Ethanol | V35: 1 | W35: Ja, da nur geringe Stoffmengen verwendet werden (für analytische Zwecke, Proben, Kleinarbeiten) | X35: Schutzleitfaden-100 | Y35: Freie Lüftung | Z35: Schutzleitfaden-120 | AA35: Organisations- und Hygienemaßnahmen "Haut" | AB35: Schutzleitfaden-PC170 | AC35: Brandschutzmaßnahmen | AD35: - | AE35: 0 | AF35: - | AG35: keine | AH35: entfällt | AI35: - | AJ35: 0 | AK35: - | AL35: keine | AM35: entfällt | AN35: - | AO35: 0 | AP35: - | AQ35: keine | AR35: entfällt | AS35: 17 | AW35: Substitutionen sind im Galvanikbereich nicht zielführend (vgl. ASA vom 05.05.2025)
A36: 033 | B36: =HYPERLINK(CONCATENATE("..\SDB\SDB_",A36,".pdf"),"2") -> 2 | C36: =HYPERLINK("#"&CONCATENATE(A36,"!B1"),"2") -> 2 | D36: Natrium-EDTA-Lösung 0,05 mol/l - 1/20 M Lösung Titriermittel für METROHM | E36: Bernd Kraft GmbH | F36: 44525 | G36: Flüssigkeit | H36: farblos | I36: Gemisch | J36: Chemische Analytik | K36: GHS 05, Achtung | L36: H290 | M36: - | N36: - | O36: - | P36: - | Q36: P234 | R36: P390 | S36: P406 | T36: - | U36: - | V36: 1 | W36: Ja, da nur geringe Stoffmengen verwendet werden (für analytische Zwecke, Proben, Kleinarbeiten) | X36: Schutzleitfaden-200 | Y36: Örtliche Absaugung (Punktabsaugung) | Z36: Schutzleitfaden-120 | AA36: Organisations- und Hygienemaßnahmen "Haut" | AB36: Schutzleitfaden-PC170 | AC36: Brandschutzmaßnahmen | AD36: - | AE36: 0 | AF36: - | AG36: keine | AH36: entfällt | AI36: - | AJ36: 0 | AK36: - | AL36: keine | AM36: entfällt | AN36: - | AO36: 0 | AP36: - | AQ36: keine | AR36: entfällt | AS36: - | AW36: Substitutionen sind im Galvanikbereich nicht zielführend (vgl. ASA vom 05.05.2025)
A37: 034 | B37: =HYPERLINK(CONCATENATE("..\SDB\SDB_",A37,".pdf"),"2") -> 2 | C37: =HYPERLINK("#"&CONCATENATE(A37,"!B1"),"2") -> 2 | D37: Iodid-Iodat-Lösung | E37: Bernd Kraft GmbH | F37: 44820 | G37: Flüssigkeit | H37: farblos | I37: Gemisch | J37: Chemische Analytik | K37: GHS 08, Achtung | L37: - | M37: H373 | N37: - | O37: - | P37: - | Q37: P260 | R37: P314 | S37: - | T37: - | U37: - | V37: 3 | W37: Ja, da nur geringe Stoffmengen verwendet werden (für analytische Zwecke, Proben, Kleinarbeiten) | X37: Schutzleitfaden-200 | Y37: Örtliche Absaugung (Punktabsaugung) | Z37: Schutzleitfaden-120 | AA37: Organisations- und Hygienemaßnahmen "Haut" | AB37: Schutzleitfaden-PC170 | AC37: Brandschutzmaßnahmen | AD37: - | AE37: 0 | AF37: - | AG37: keine | AH37: entfällt | AI37: - | AJ37: 0 | AK37: - | AL37: keine | AM37: entfällt | AN37: - | AO37: 0 | AP37: - | AQ37: keine | AR37: entfällt | AS37: - | AW37: Substitutionen sind im Galvanikbereich nicht zielführend (vgl. ASA vom 05.05.2025)
A38: 035 | B38: =HYPERLINK(CONCATENATE("..\SDB\SDB_",A38,".pdf"),"2") -> 2 | C38: =HYPERLINK("#"&CONCATENATE(A38,"!B1"),"2") -> 2 | D38: Alficlean 139 | E38: Alufinish GmbH & Co. KG | F38: 45303 | G38: Feststoff | H38: gelblich | I38: Gemisch | J38: Metalloberflächenbehandlung | K38: GHS 05, GHS 08, Gefahr | L38: - | M38: H318, H360FD | N38: H412 | O38: - | P38: - | Q38: P201, P273, P280 | R38: P305+P351+P338, P310, P308+P313 | S38: - | T38: - | U38: Boraxdecahydrat | V38: 2 | W38: Nein, da gefährliche Einstufungen und Eigenschaften vorliegen (siehe EMKG). | X38: Beratung | Y38: siehe tätigkeitsspezifische Gefährdungsbeurteilung | Z38: Schutzleitfaden-250 | AA38: Erweiterter Maßnahmenbedarf „Haut“ | AB38: Schutzleitfaden-PC170 | AC38: Brandschutzmaßnahmen | AD38: Boraxdecahydrat | AE38: 25 - 50 | AF38: Kat. 1B | AG38: H360FD | AH38: Kann die Fruchtbarkeit beeinträchtigen. Kann das Kind im Mutterleib schädigen. | AI38: - | AJ38: 0 | AK38: - | AL38: keine | AM38: entfällt | AN38: - | AO38: 0 | AP38: - | AQ38: keine | AR38: entfällt | AS38: - | AW38: Substitutionen sind im Galvanikbereich nicht zielführend (vgl. ASA vom 05.05.2025)
A39: 036 | B39: =HYPERLINK(CONCATENATE("..\SDB\SDB_",A39,".pdf"),"2") -> 2 | C39: =HYPERLINK("#"&CONCATENATE(A39,"!B1"),"2") -> 2 | D39: Kalilauge 6 mol/l | E39: Bernd Kraft GmbH | F39: 45274 | G39: Flüssigkeit | H39: farblos | I39: Gemisch | J39: Chemische Analytik | K39: GHS 05, GHS 07, Gefahr | L39: H290 | M39: H302, H314 | N39: - | O39: - | P39: - | Q39: P280 | R39: P305+P351+P338, P303+P361+P353, P309, P310, P301+P330+P331 | S39: - | T39: - | U39: - | V39: 1 | W39: Ja, da nur geringe Stoffmengen verwendet werden (für analytische Zwecke, Proben, Kleinarbeiten) | X39: Schutzleitfaden-200 | Y39: Örtliche Absaugung (Punktabsaugung) | Z39: Gefährdungsbeurteilung | AA39: siehe gefahrstoffspezifische Gefährdungsbeurteilung | AB39: Schutzleitfaden-PC170 | AC39: Brandschutzmaßnahmen | AD39: - | AE39: 0 | AF39: - | AG39: keine | AH39: entfällt | AI39: - | AJ39: 0 | AK39: - | AL39: keine | AM39: entfällt | AN39: - | AO39: 0 | AP39: - | AQ39: keine | AR39: entfällt | AS39: - | AW39: Substitutionen sind im Galvanikbereich nicht zielführend (vgl. ASA vom 05.05.2025)
A40: 037 | B40: =HYPERLINK(CONCATENATE("..\SDB\SDB_",A40,".pdf"),"2") -> 2 | C40: =HYPERLINK("#"&CONCATENATE(A40,"!B1"),"2") -> 2 | D40: Kaliumchromat 10% Lösung | E40: CHEM-LAB NV | F40: 43434 | G40: Flüssigkeit | H40: orange | I40: Gemisch | J40: Chemische Analytik | K40: GHS 07, GHS 08, GHS 09, Gefahr | L40: - | M40: H315, H317, H319, H335, H340, H350 | N40: H410 | O40: - | P40: - | Q40: P201, P273, P280 | R40: P308 + P313, P305 + P351 + P338, P302 + P352 | S40: - | T40: - | U40: - | V40: 1 | W40: Ja, da nur geringe Stoffmengen verwendet werden (für analytische Zwecke, Proben, Kleinarbeiten) | X40: Beratung | Y40: siehe tätigkeitsspezifische Gefährdungsbeurteilung | Z40: Gefährdungsbeurteilung | AA40: siehe gefahrstoffspezifische Gefährdungsbeurteilung | AB40: Schutzleitfaden-PC170 | AC40: Brandschutzmaßnahmen | AD40: Kaliumchromat | AE40: 10 | AF40: Kat. 1B | AG40: H340 | AH40: Kann genetische Defekte verursachen. | AI40: Kaliumchromat | AJ40: 10 | AK40: Kat. 1B | AL40: H350 | AM40: Kann Krebs erzeugen. | AN40: - | AO40: 0 | AP40: - | AQ40: keine | AR40: entfällt | AS40: - | AW40: Substitutionen sind im Galvanikbereich nicht zielführend (vgl. ASA vom 05.05.2025)
...

Sheet Daten
A1: Gefährdungsfaktoren | G1: Name des Unternehmens | H1: Anschrift | I1: Status | J1: WGK | K1: WGK_Bezechnung | L1: PSA_Handschutz | M1: PSA_Augenschutz | N1: PSA_Atemschutz | O1: PSA_Körperschutz
A2: 1 | B2: Maßnahmenstufe 1 | C2: Mindeststandards | G2: OTH Oberflächentechnik Hagen GmbH & Co. KG | H2: Selbecker Str. 145-149, 58091 Hagen | I2: o | J2: nwg | K2: nwg: nicht wassergefährdend | L2: Chemikalien-Schutzhandschuhe | M2: Dichtschließende Schutzbrille mit Seitenschutz | N2: Vollmaske | O2: Einwegoverall
A3: 1.1 | B3: Schutzleitfaden-100 | C3: Freie Lüftung | F3: =HYPERLINK(CONCATENATE("Schutzleitfäden\",B3,".pdf"),2) -> 2 | I3: þ | J3: awg | K3: awg: allgemein wassergefährdend | L3: (nicht definiert) | M3: (nicht definiert) | N3: Halbmaske | O3: Arbeitskleidung
A4: 1.2 | B4: Schutzleitfaden-LA101 | C4: Bereitstellen und Lagern | F4: =HYPERLINK(CONCATENATE("Schutzleitfäden\",B4,".pdf"),2) -> 2 | G4: Verantwortliche Führungskraft | H4: Funktion | I4: ý | J4: 1 | K4: WGK 1: schwach wassergefährdend | L4: (nicht erforderlich) | M4: (nicht erforderlich) | N4: FFP2-Staubschutzmaske | O4: (nicht definiert)
A5: 1.3 | B5: Schutzleitfaden-102 | C5: Lagerung von Schüttgütern | F5: =HYPERLINK(CONCATENATE("Schutzleitfäden\",B5,".pdf"),2) -> 2 | G5: Herr Udo Gensowski | H5: Geschäftsführer | J5: 2 | K5: WGK 2: wassergefährdend | N5: Kombinationsfiltergerät | O5: (nicht erforderlich)
A6: 1.4 | B6: Schutzleitfaden-110 | C6: Organisations-und Hygienemaßnahmen "Einatmen" | F6: =HYPERLINK(CONCATENATE("Schutzleitfäden\",B6,".pdf"),2) -> 2 | J6: 3 | K6: WGK 3: stark wassergefährdend | N6: (nicht definiert)
A7: 1.5 | B7: Schutzleitfaden-120 | C7: Organisations-und Hygienemaßnahmen "Haut" | F7: =HYPERLINK(CONCATENATE("Schutzleitfäden\",B7,".pdf"),2) -> 2 | N7: (nicht erforderlich)
A8: 1.6 | B8: Schutzleitfaden-130 | C8: Drucken, Kopieren | F8: =HYPERLINK(CONCATENATE("Schutzleitfäden\",B8,".pdf"),2) -> 2
A9: 2 | B9: Maßnahmenstufe 2 | C9: Emissionsmindernde Maßnahmen
A10: 2.1 | B10: Schutzleitfaden-200 | C10: Örtliche Absaugung (Punktabsaugung) | F10: =HYPERLINK(CONCATENATE("Schutzleitfäden\",B10,".pdf"),2) -> 2
A11: 2.2 | B11: Schutzleitfaden-201 | C11: Abzugsschränke | F11: =HYPERLINK(CONCATENATE("Schutzleitfäden\",B11,".pdf"),2) -> 2
A12: 2.3 | B12: Schutzleitfaden-203 | C12: Absaugschrank | F12: =HYPERLINK(CONCATENATE("Schutzleitfäden\",B12,".pdf"),2) -> 2
A13: 2.4 | B13: Schutzleitfaden-204 | C13: Staubentnahme aus Abscheidesystem | F13: =HYPERLINK(CONCATENATE("Schutzleitfäden\",B13,".pdf"),2) -> 2
A14: 2.5 | B14: Schutzleitfaden-205 | C14: Transport über Förderband | F14: =HYPERLINK(CONCATENATE("Schutzleitfäden\",B14,".pdf"),2) -> 2
A15: 2.6 | B15: Schutzleitfaden-206 | C15: Befüllen von Säcken | F15: =HYPERLINK(CONCATENATE("Schutzleitfäden\",B15,".pdf"),2) -> 2
A16: 2.7 | B16: Schutzleitfaden-208 | C16: Entleeren von Säcken | F16: =HYPERLINK(CONCATENATE("Schutzleitfäden\",B16,".pdf"),2) -> 2
A17: 2.8 | B17: Schutzleitfaden-210 | C17: Beschicken von Kesseln aus Säcken oder Kleingebinden | F17: =HYPERLINK(CONCATENATE("Schutzleitfäden\",B17,".pdf"),2) -> 2
A18: 2.9 | B18: Schutzleitfaden-211 | C18: Befüllung und Entleerung von Containern (IBC) | F18: =HYPERLINK(CONCATENATE("Schutzleitfäden\",B18,".pdf"),2) -> 2
A19: 2.10 | B19: Schutzleitfaden-212 | C19: Befüllen von Fässern | F19: =HYPERLINK(CONCATENATE("Schutzleitfäden\",B19,".pdf"),2) -> 2
A20: 2.11 | B20: Schutzleitfaden-213 | C20: Entleeren von Fässern mittels Fasspumpe | F20: =HYPERLINK(CONCATENATE("Schutzleitfäden\",B20,".pdf"),2) -> 2
A21: 2.12 | B21: Schutzleitfaden-214 | C21: Wiegen von Feststoffen | F21: =HYPERLINK(CONCATENATE("Schutzleitfäden\",B21,".pdf"),2) -> 2
... A29: 2.20 | B29: Schutzleitfaden-260 | C29: Wartungs- und Servicearbeiten an Drucker- und Kopiergeräten | F29: =HYPERLINK(CONCATENATE("Schutzleitfäden\",B29,".pdf"),2) -> 2
A30: 3 | B30: Maßnahmenstufe 2a | C30: Schutzleitfaden für Hautkontakt
A31: 3.1 | B31: Schutzleitfaden-250 | C31: Erweiterter Maßnahmenbedarf „Haut“ | F31: =HYPERLINK(CONCATENATE("Schutzleitfäden\",B31,".pdf"),2) -> 2
A32: 4 | B32: Maßnahmenstufe 2b | C32: Schutzleitfäden für Brand und Explosion
A33: 4.1 | B33: Schutzleitfaden-PC170 | C33: Brandschutzmaßnahmen | F33: =HYPERLINK(CONCATENATE("Schutzleitfäden\",B33,".pdf"),2) -> 2
A34: 4.2 | B34: Schutzleitfaden-PC270 | C34: Grundanforderungen bei erhöhter Brandgefährdung | F34: =HYPERLINK(CONCATENATE("Schutzleitfäden\",B34,".pdf"),2) -> 2
A35: 4.3 | B35: Schutzleitfaden-PC271 | C35: Lackierarbeiten, Spritz- und Beschichtungsverfahren | F35: =HYPERLINK(CONCATENATE("Schutzleitfäden\",B35,".pdf"),2) -> 2
A36: 4.4 | B36: Schutzleitfaden-PC280 | C36: Grundlegende Explosionsschutzmaßnahmen | F36: =HYPERLINK(CONCATENATE("Schutzleitfäden\",B36,".pdf"),2) -> 2
A37: 4.5 | B37: Schutzleitfaden-PC281 | C37: Brennbare Flüssigkeiten umfüllen und abfüllen | F37: =HYPERLINK(CONCATENATE("Schutzleitfäden\",B37,".pdf"),2) -> 2
A38: 4.6 | B38: Schutzleitfaden-PC282 | C38: Lackierarbeiten, Spritz- und Beschichtungsverfahren | F38: =HYPERLINK(CONCATENATE("Schutzleitfäden\",B38,".pdf"),2) -> 2
A39: 4.7 | B39: Schutzleitfaden-PC370 | C39: Hohe Brandschutzmaßnahmen - Grundanforderungen | F39: =HYPERLINK(CONCATENATE("Schutzleitfäden\",B39,".pdf"),2) -> 2
A40: 5 | B40: Maßnahmenstufe 3a
A41: 5.1 | B41: Schutzleitfaden-300 | C41: Geschlossenes System | F41: =HYPERLINK(CONCATENATE("Schutzleitfäden\",B41,".pdf"),2) -> 2
A42: 5.2 | B42: Schutzleitfaden-301 | C42: Handschuhkasten (glove box) | F42: =HYPERLINK(CONCATENATE("Schutzleitfäden\",B42,".pdf"),2) -> 2
A43: 5.3 | B43: Schutzleitfaden-305 | C43: Fassbefüllung | F43: =HYPERLINK(CONCATENATE("Schutzleitfäden\",B43,".pdf"),2) -> 2
A44: 5.4 | B44: Schutzleitfaden-306 | C44: Fassentleerung | F44: =HYPERLINK(CONCATENATE("Schutzleitfäden\",B44,".pdf"),2) -> 2
A45: 5.5 | B45: Schutzleitfaden-307 | C45: Befüllung und Entleerung von IBC-Containern (Feststoffe) | F45: =HYPERLINK(CONCATENATE("Schutzleitfäden\",B45,".pdf"),2) -> 2
A46: 5.6 | B46: Schutzleitfaden-308 | C46: Befüllung und Entleerung von IBC-Containern (Flüssigkeiten) | F46: =HYPERLINK(CONCATENATE("Schutzleitfäden\",B46,".pdf"),2) -> 2
A47: 5.7 | B47: Schutzleitfaden-310 | C47: Befüllen und Entleeren von Tankfahrzeugen | F47: =HYPERLINK(CONCATENATE("Schutzleitfäden\",B47,".pdf"),2) -> 2
...

Sheet Maßnahmen
B1: Kap | C1: Sub | D1: lfd. Nr | E1: Gefährdungsfaktoren | F1: Schutzmaßnahmen und Verhaltensregeln | G1: Status | H1: wirksam am
B2: 1 | E2: =IF(B2=0,"",VLOOKUP(B2,Daten!$A$1:$B$56,2,FALSE)) -> Maßnahmenstufe 1 | F2: =VLOOKUP(E2,Daten!$B$2:$C$56,2,) -> Mindeststandards
B3: 1.1 | E3: =IF(B3=0,"",VLOOKUP(B3,Daten!$A$2:$B$56,2,FALSE)) -> Schutzleitfaden-100 | F3: =VLOOKUP(E3,Daten!$B$2:$C$56,2,) -> Freie Lüftung
B4: 1 | C4: 1 | D4: =ROW(A4)-(ROW(A$3)) -> 1 | E4: Mangel an gesundheitlich zuträglicher Atemluft | F4: Ein muss ausreichendes Maß an gesundheitlich zuträglicher Atemluft sichergestellt sein (z. B. durch Fenster, Türen, Schacht-, Dachaufsätze, Kaminlüftung, Kuppeln und sonstige Lüftungsöffnungen, ggf. unterstützt durch Ventilatoren). | G4: prüfen
B5: 1 | C5: 1 | D5: =ROW(A5)-(ROW(A$3)) -> 2 | E5: Atemluft aus verunreinigten Quellen | F5: Die zugeführte Frischluft darf nicht aus verunreinigter Quelle stammen. | G5: prüfen
B6: 1 | C6: 1 | D6: =ROW(A6)-(ROW(A$3)) -> 3 | E6: Schlechte Zugänglichkeit und schwergängige Bedienung von Zu- und Abluftöffnungen | F6: Zu- und Abluftöffnungen müssen leicht zugänglich und sicher zu bedienen sein . | G6: prüfen
B7: 1 | C7: 1 | D7: =ROW(A7)-(ROW(A$3)) -> 4 | E7: Eingeschränkte Wirksamkeit von Zu- und Abluftöffnungen durch falsche Platzierung | F7: Zu- und Abluftöffnungen sollten so gewählt sein , dass die Wirksamkeit der Lüftung nicht eingeschränkt wird. | G7: prüfen
B8: 1 | C8: 1 | D8: =ROW(A8)-(ROW(A$3)) -> 5 | E8: Zugestellte Lüftungsgitter und -öffnungen | F8: Lüftungsgitter und -öffnungen dürfen nicht zugestellt werden. | G8: prüfen
B9: 1 | C9: 1 | D9: =ROW(A9)-(ROW(A$3)) -> 6 | E9: Schadhafte, nicht funktionierende Lüftungsgitter und -öffnungen | F9: Lüftungsgitter und -öffnungen müssen regelmäßig auf Schäden und Funktionsfähigkeit geprüft werden. | G9: prüfen
B10: 1 | C10: 1 | D10: =ROW(A10)-(ROW(A$3)) -> 7 | E10: Schmutz und Verunreinigungen an Lüftungsgitter und -öffnungen | F10: Ablagerungen und Verunreinigungen an Lüftungsgittern und -öffnungen müssen sofort beseitigt werden. | G10: prüfen
B11: 1 | C11: 1 | D11: =ROW(A11)-(ROW(A$3)) -> 8 | E11: Geruchsbelästigende Gefahrstoffe | F11: Bei Beschwerden der Beschäftigten über geruchsbelästigende Gefahrstoffe sollen ggf. weitergehende Maßnahmen festgelegt werden. | G11: prüfen
B12: 1 | C12: 1 | D12: =ROW(A12)-(ROW(A$3)) -> 9 | E12: Eingeschränkte Lüftungsverhältnissen | F12: Bei eingeschränkten Lüftungsverhältnissen muss die Notwendigkeit einer RLT-Anlage geprüft werden. Eingeschränkte Lüftungsverhältnisse haben z.B. tiefe Gruben, enge Räume oder Räume mit hohen Stellwänden, Schränke oder Regale sowie Räume ohne ausreichende Lüftungsmöglichkeit. | G12: prüfen
B13: 1 | C13: 1 | D13: =ROW(A13)-(ROW(A$3)) -> 10 | E13: Zugluft | F13: Dauer und Intensität des Luftaustausches sollte so gestaltet werden, dass Zugluft vermieden wird. | G13: prüfen
B14: 1 | C14: 1 | D14: =ROW(A14)-(ROW(A$3)) -> 11 | E14: Mangel an gesundheitlich zuträglicher Atemluft | F14: Durch eine kontinuierliche Lüftung oder regelmäßige Stoßlüftung muss sichergestellt werden, dass genügend gesundheitlich zuträgliche Atemluft zur Verfügung steht. | G14: prüfen
B15: 1 | C15: 1 | D15: =ROW(A15)-(ROW(A$3)) -> 12 | E15: Gebrauch von lösungsmittelhaltigen Stoffen | F15: Bei flächigem Auftrag von Lösemitteln (z.B. beim Verstreichen von Lacken, Klebstoffen etc.) müssen Fenster/Türen geöffnet sein. | G15: prüfen
B16: 1 | C16: 1 | D16: =ROW(A16)-(ROW(A$3)) -> 13 | E16: Nichteinhalten der ASR A1.6 Anforderungen | F16: Die Anforderungen der ASR A1.6 -Fenster, Oberlichter, lichtdurchlässige Wände - müssen beim Einrichten und Betreiben der Arbeitsstätte beachtet werden. | G16: prüfen
B17: 1.2 | E17: =IF(B17=0,"",VLOOKUP(B17,Daten!$A$2:$B$56,2,FALSE)) -> Schutzleitfaden-LA101 | F17: =VLOOKUP(E17,Daten!$B$2:$C$56,2,) -> Bereitstellen und Lagern
B18: 1 | C18: 2 | D18: =ROW(A18)-(ROW(A$17)) -> 1 | E18: Unzureichende Belastbarkeit und Standsicherheit | F18: Lagereinrichtungen müssen statisch belastbar und standsicher sein. | G18: prüfen
B19: 1 | C19: 2 | D19: =ROW(A19)-(ROW(A$17)) -> 2 | E19: Unübersichtliche Lagerung | F19: Einrichtung und Ausstattung des Lagers soll so gestaltet sein, dass eine übersichtliche Lagerung der Gefahrstoffe möglich ist. | G19: prüfen
B20: 1 | C20: 2 | D20: =ROW(A20)-(ROW(A$17)) -> 3 | E20: Fehlerhafte Montage der Regale | F20: Regale müssen entsprechend der Montageanleitung aufgebaut werden. | G20: prüfen
B21: 1 | C21: 2 | D21: =ROW(A21)-(ROW(A$17)) -> 4 | E21: Fehlender Anfahrschutz bei freistehenden Lagereinrichtungen und Behältern. | F21: Freistehende Lagereinrichtungen und Behälter (z.B. Regale, IBC-Container) müssen durch einen Anfahrschutz vor Leckagen geschützt. | G21: prüfen
B22: 1 | C22: 2 | D22: =ROW(A22)-(ROW(A$17)) -> 5 | E22: Fehlende Standsicherheit von Regalen aufgrund des Untergrundes | F22: Regale müssen auf einen ebenen Untergrund mit ausreichender Festigkeit gestellt werden. | G22: prüfen
B23: 1 | C23: 2 | D23: =ROW(A23)-(ROW(A$17)) -> 6 | E23: Fehlende/mangelhafte Auffangbehälter im Fall von Leckagen | F23: Im Leckagefall müssen Flüssigkeiten und Flüssiggase in chemikalienbeständige Auffangwannen oder Auffangräume aufgefangen werden. Keinesfalls in Abflüsse, Gruben, Kanäle und Kellerräume. | G23: prüfen
B24: 1 | C24: 2 | D24: =ROW(A24)-(ROW(A$17)) -> 7 | E24: Nicht ausreichende Kapazitäten von Auffangeinrichtungen | F24: Die Kapazität von Auffangeinrichtungen muss mindestens 10% der Gesamtmenge bzw. des Fassungsvermögens des größten Behälters betragen. | G24: prüfen
B25: 1 | C25: 2 | D25: =ROW(A25)-(ROW(A$17)) -> 8 | E25: Ungeeignete Fußböden und Auffangwannen | F25: Fußböden und Auffangwannen müssen für das Lagergut geeignet sein , z.B. elektrostatisch ableitfähig bei entzündbaren Flüssigkeiten. | G25: prüfen
B26: 1 | C26: 2 | D26: =ROW(A26)-(ROW(A$17)) -> 9 | E26: Unzulässige Lagerung von Gefahrstoffen | F26: Gefahrstoffe müssen abhängig von der Stoffeigenschaft und Mengen in einem Lager gelagert werden. Gefahrstofflager sind z.B. Lagerraum, Sicherheitsschrank oder Container. | G26: prüfen
B27: 1 | C27: 2 | D27: =ROW(A27)-(ROW(A$17)) -> 10 | E27: Unzulässige Menge an Gefahrstoffen am Arbeitsplatz | F27: Am Arbeitsplatz darf nur die für den Tages- oder Schichtbedarf erforderliche Menge an Gefahrstoff bereitgestellt werden. Bei regelmäßigen Tätigkeiten mit kleinen Mengen muss die jeweils handelsüblich kleinste Gebindegröße bereitgestellt werden. | G27: prüfen
B28: 1 | C28: 2 | D28: =ROW(A28)-(ROW(A$17)) -> 11 | E28: Gefahr durch Lagerung entzündlicher Flüssigkeiten in zerbrechlichen Behältern. | F28: Entzündbare Flüssigkeiten sollen, wenn möglich, in nicht zerbrechlichen Behältern gelagert werden. Außerhalb des Lagers dürfen entzündbare Flüssigkeiten in nicht zerbrechlichen Behältern bis maximal 10 l Fassungsvermögen je Behälter gelagert werden. In zerbrechlichen Behältern bis 2,5 l Fassungsvermögen je Behälter. | G28: prüfen
B29: 1 | C29: 2 | D29: =ROW(A29)-(ROW(A$17)) -> 12 | E29: Belastung der Atemluft durch nicht regelmäßig entleerte Auffangeinrichtungen. | F29: Auffangeinrichtungen müssen regelmäßig entleert werden und dürfen nicht zu einer zusätzlichen Belastung der Atemluft führen. | G29: prüfen
... B52: 1 | C52: 2 | D52: =ROW(A52)-(ROW(A$17)) -> 35 | E52: Nichtbeachtung der Brand- und Explosionsschutzmaßnahmen | F52: Brand- und Explosionsschutzmaßnahmen müssen zusätzlich beachtet werden. | G52: prüfen
B53: 1.3 | E53: =IF(B53=0,"",VLOOKUP(B53,Daten!$A$2:$B$56,2,FALSE)) -> Schutzleitfaden-102 | F53: =VLOOKUP(E53,Daten!$B$2:$C$56,2,) -> Lagerung von Schüttgütern
B54: 1 | C54: 3 | D54: =ROW(A54)-(ROW(A$53)) -> 1 | E54: Unbefugte Personen im Arbeitsbereich | F54: Zugang des Arbeitsbereiches nur für Befugte. | G54: prüfen
B55: 1 | C55: 3 | D55: =ROW(A55)-(ROW(A$53)) -> 2 | E55: Lagerhallenöffnung zur Hauptwindrichtung | F55: Lagerhallenöffnungen möglichst nicht zur Hauptwindrichtung. | G55: prüfen
B56: 1 | C56: 3 | D56: =ROW(A56)-(ROW(A$53)) -> 3 | E56: Fehlende oder unzureichende Lagerflächenkennzeichnung | F56: Klare Lagerflächenkennzeichnung. | G56: prüfen
B57: 1 | C57: 3 | D57: =ROW(A57)-(ROW(A$53)) -> 4 | E57: Staubentwicklung aufgrund fehlerhafter Platzierung der Abzugseinrichtung | F57: Abzugseinrichtung so nah wie möglich an die Staubquelle platzieren. | G57: prüfen
B58: 1 | C58: 3 | D58: =ROW(A58)-(ROW(A$53)) -> 5 | E58: Staubentwicklung im gesamten Bereich aufgrund fehlender Raumabtrennungen | F58: Bereitstellung von Abtrennungen zur Verringerung von Staubausbreitung in der gesamten Halle. | G58: prüfen
B59: 1 | C59: 3 | D59: =ROW(A59)-(ROW(A$53)) -> 6 | E59: Keine Trennung von unterschiedlichen Halden | F59: Klare Trennung von unterschiedlichen Halden. | G59: prüfen
B60: 1 | C60: 3 | D60: =ROW(A60)-(ROW(A$53)) -> 7 | E60: Lagerung von brennbaren Materialien in der Halle | F60: Leicht brennbare Materialien, wie leere Verpackungen, in einem separaten Raum lagern. | G60: prüfen
B61: 1 | C61: 3 | D61: =ROW(A61)-(ROW(A$53)) -> 8 | E61: Mangelhafte Wartung und Instandhaltung der Einrichtungen und Ausrüstungen | F61: Einrichtungen und Ausrüstungen entsprechend den Herstellerangaben instand halten und warten. | G61: prüfen
B62: 1 | C62: 3 | D62: =ROW(A62)-(ROW(A$53)) -> 9 | E62: Fehlende monatliche Sichtkontrolle der Lüftungsanlage | F62: Durchführung einer Sichtkontrolle der Lüftungsanlage auf Anzeichen von Beschädigungen einmal im Monat. | G62: prüfen
...

Sheet 000
B1: Gefährdungsbeurteilung für Gefahrstoffe nach § 6 GefStoffV, TRGS 400 | F1: Nummer: | G1: 000
B2: =CONCATENATE(Daten!G2," · ",Daten!H2) -> OTH Oberflächentechnik Hagen GmbH & Co. KG · Selbecker Str. 145-149, 58091 Hagen | F2: Stand: | G2: =TODAY() -> 45905
D5: Bearbeiter: | E5: Herr Kim Marius Gräfe (Fachkraft für Arbeitssicherheit)
D6: Verantwortliche Führungskraft: | E6: =CONCATENATE(Daten!G5," (",Daten!H5,")") -> Herr Udo Gensowski (Geschäftsführer)
B8: Allgemeine Angaben
D10: Produktbezeichnung / Handelsname: | E10: =VLOOKUP($G$1,'Übersicht GBU'!A:AB,4,FALSE) -> #N/A
D11: Hersteller / Lieferant: | E11: =VLOOKUP($G$1,'Übersicht GBU'!A:AB,5,FALSE) -> #N/A
D12: Sicherheitsdatenblatt vom: | E12: =VLOOKUP($G$1,'Übersicht GBU'!A:AB,6,FALSE) -> #N/A
D13: Zustandsform: | E13: =CONCATENATE(VLOOKUP($G$1,'Übersicht GBU'!A:AB,7,FALSE),", ",VLOOKUP($G$1,'Übersicht GBU'!A:AB,8,FALSE)," (",VLOOKUP($G$1,'Übersicht GBU'!A:AB,9,FALSE),")") -> #N/A
D14: Einsatzweck / interne Verwendung: | E14: =VLOOKUP($G$1,'Übersicht GBU'!A:AB,10,FALSE) -> #N/A
D16: Beschreibung der Tätigkeit, Häufigkeit der Anwendung, Lager- und Verwendungsmengen am Arbeitsplatz: | E16: Der Gefahrstoff wird zum xxxxx eingesetzt. | G16: Achtung Gefahr
B18: Einstufung und Gefahren / Toxikologie
D20: Kennzeichnung gemäß CLP-VO (EG) 1272/2008: | E20: =VLOOKUP($G$1,'Übersicht GBU'!A:AB,11,FALSE) -> #N/A
D21: H-Sätze [H2XX / H3XX / H4XX / EUHXXX]: | E21: =CONCATENATE(VLOOKUP($G$1,'Übersicht GBU'!A:AB,12,FALSE)," / ",(VLOOKUP($G$1,'Übersicht GBU'!A:AB,13,FALSE))," / ",(VLOOKUP($G$1,'Übersicht GBU'!A:AB,14,FALSE))," / ",(VLOOKUP($G$1,'Übersicht GBU'!A:AB,15,FALSE))) -> #N/A
D22: P-Sätze [P1XX / P2XX / P3XX / P4XX / P5XX]: | E22: =CONCATENATE(VLOOKUP($G$1,'Übersicht GBU'!A:AB,16,FALSE)," / ",(VLOOKUP($G$1,'Übersicht GBU'!A:AB,17,FALSE))," / ",(VLOOKUP($G$1,'Übersicht GBU'!A:AB,18,FALSE))," / ",(VLOOKUP($G$1,'Übersicht GBU'!A:AB,19,FALSE))," / ",(VLOOKUP($G$1,'Übersicht GBU'!A:AB,20,FALSE))) -> #N/A
D23: Tätigkeiten mit geringer Gefährdung (TRGS 400): | E23: =VLOOKUP($G$1,'Übersicht GBU'!A:AB,23,FALSE) -> #N/A
D24: Wassergefährdungsklasse (WGK): | E24: =VLOOKUP(G24,Daten!J2:K6,2,FALSE) -> #N/A | G24: =VLOOKUP($G$1,'Übersicht GBU'!A:AB,22,FALSE) -> #N/A
J25: H400, H410, H411, H412
D26: Arbeitsplatzgrenzwerte (TRGS 900): | E26: =VLOOKUP($G$1,'Übersicht GBU'!A:AB,21,FALSE) -> #N/A
D27: Angaben zu den CMR-Bestandteilen: | E27: =CONCATENATE(VLOOKUP($G$1,'Übersicht GBU'!A:AR,30,FALSE)," (",(VLOOKUP($G$1,'Übersicht GBU'!A:AR,31,FALSE)),"%), ",(VLOOKUP($G$1,'Übersicht GBU'!A:AR,32,FALSE))," / ",(VLOOKUP($G$1,'Übersicht GBU'!A:AR,33,FALSE))," - ",(VLOOKUP($G$1,'Übersicht GBU'!A:AR,34,FALSE))) -> #N/A
E28: =CONCATENATE(VLOOKUP($G$1,'Übersicht GBU'!A:AR,35,FALSE)," (",(VLOOKUP($G$1,'Übersicht GBU'!A:AR,36,FALSE)),"%), ",(VLOOKUP($G$1,'Übersicht GBU'!A:AR,37,FALSE))," / ",(VLOOKUP($G$1,'Übersicht GBU'!A:AR,38,FALSE))," - ",(VLOOKUP($G$1,'Übersicht GBU'!A:AR,39,FALSE))) -> #N/A
B30: Expositionsbeschreibung
D32: Beschreibung von Ausmaß, Art und Dauer der Exposition / Expositionswege: | E32: Die gefahrbringende Komponente ist
B34: Anwendung der Technischen Regeln für Gefahrstoffe (TRGS) | G34: trifft zu
D36: Gefährdungen durch Hautkontakt (TRGS 401): | G36: o
D37: Hautgefährdende Eigenschaften: | G37: o | J37: H314, H315, H317, EUH066, EUH204, EUH205, EUH208
D38: Hautresorptive Eigenschaften: | G38: o | J38: H310, H311, H312, H370, H371, H372, H373
D39: Sonstige hautgefährdende Eigenschaften: | G39: o | J39: wirkt entfettend // Gefahr der Hautresorption
D40: Tätigkeitsbedingte Feuchtarbeit: | G40: o | J40: Kontakt mit wässrigen Flüssigkeiten >2 Std./Tag; Händewaschen >15x/Tag
D41: Verletzung der Haut bei der Tätigkeit: | G41: o | J41: z. B. Schnitte, Stiche, scharfkantige Partikel oder künstliche Mineralfasern
D42: Besondere physikalische Bedingungen: | G42: o | J42: z. B. Hitze, Kälte, UV-Strahlung
D43: Sichtbare Verschmutzung der Haut: | G43: o
D44: Maßnahmenreihe nach EMGK "Hautkontakt": | E44: =CONCATENATE(VLOOKUP($G$1,'Übersicht GBU'!A:AB,26,FALSE)," (",VLOOKUP($G$1,'Übersicht GBU'!A:AB,27,FALSE),")") -> #N/A | G44: o
E45: Die allgemeinen Hautschutz- und Hygienemaßnahmen werden eingehalten. | G45: o | J45: Die allgemeinen Hautschutz- und Hygienemaßnahmen werden eingehalten.
